Workbook

Sheet Preço Soja ESALQ
B1: Data final | C1: =TODAY() -> 46143 | E1: 3 | F1: =+E1+1 -> 4 | G1: =+F1+1 -> 5 | H1: =+G1+1 -> 6 | I1: =+H1+1 -> 7 | J1: =+I1+1 -> 8 | K1: =+J1+1 -> 9 | L1: =+K1+1 -> 10 | M1: =+L1+1 -> 11 | ... BN1: =+BM1+1 -> 64
C2: =_xll.RDP.HistoricalPricing($A$4:$A$65,"CLOSE","START:01-Jan-2015 END:"&$C$1&" SOURCE:RFV INTERVAL:P1D",,"CH:IN RH:Timestamp TSREPEAT:NO",D4) -> #NAME? | D2: INST_DESC | E2: Soy Meal Ponta Grossa, PR | F2: Soy Meal West Parana | G2: Soy Meal North Parana | H2: Soy Meal Triangulo Mineiro MG | I2: Soy Meal Chapeco, SC | J2: Soy Meal Campinas, Sao Pau | K2: Soy Meal Passo Fundo, RS | L2: Soy Meal Campo Grande, MS | M2: Soy Meal Rondonopolis, MT | N2: Soy Meal Rio Verde, GO | O2: Soy Meal Mogiana, Sao Pau | P2: Soy Meal Ijui, RS | Q2: Soyoil Sao Paulo | R2: Soybn Grower Trian Min, MG | S2: Soybn Grower Sorriso, MT | T2: Soybn Grower Sorocabana SP | U2: Soybn Grower Rondonopolis MT | V2: Soybn Grower Rio Verde, GO | W2: Soybn Grower Ponta Grossa PR | X2: Soybn Grower Passo Fundo RS | Y2: Soybn Grower West, Parana | Z2: Soybn Grower North, Parana | AA2: Soybn Grower Mogiana, SP | AB2: Soybn Grower Ijui, RS | AC2: Soybn Grower Barreiras, BA | AD2: Soybn Grower Balsas, MA | AE2: Soybn Wholesale Passo Fundo | AF2: Soybn Wholesale Sorocabana | AG2: Soybn Wholesale Sorriso MT | AH2: Trm day Len Catle - Caceres | AI2: Trm day Len Catle - Casilandia | AJ2: Trm day Len Catle - Itamaraju | AK2: Trm day Len Cattle - Nth Goias | AL2: Trm day Len Catle - Rondonopo | AM2: Trm day Len Catle - West Bahia | AN2: BR Lean Catle Trm - Casilandia | AO2: Trm day Lean Cattle - Pantanal | AP2: BR Len Catle Cash CDI -Colider | AQ2: BR Lean Cattle Term - Caceres | AR2: BR Len Cattle Term - Itamaraju | AS2: BR Lean Catle Trm -North Goias | AT2: BR Lean Cattle Term - Pantanal | AU2: Term days Lean Cattle - Para | AV2: Trm day Len Catle - Rio Grande | AW2: BR Lean Catle Trm - Rio Grande | AX2: Soybn Wholesale Rio Verde | AY2: BR Lean Catle Trm - West Bahia | AZ2: BR Lean Catle Trm - Rondonopo | BA2: Soybn Wholesale Rondonopolis | BB2: Soybn Wholesale Ponta Grossa | BC2: Soybn Wholesale West Parana | BD2: Soybn Wholesale North Parana | BE2: Soybn-Wholesale Mogiana SP | BF2: Soybn Wholesale Triang Min | BG2: Soybn Wholesale Ijui, RS | BH2: Soybn Wholesale Barreiras BA | BI2: Soybn Grower Campos Novo | BJ2: Soybn Wholesale Campos Novo | BK2: BR Soybean - Grower Cg MS | BL2: BR Soybean - Grower Dou MS | BM2: BR Soybean - Grower Cha-MS | BN2: BR Soybean - Grower Mar MS
A3: 0#ESQ-SOY | E3: {=_xll.TR(E4,$D$2)} -> #NAME? | F3: {=_xll.TR(F4,$D$2)} -> #NAME? | G3: {=_xll.TR(G4,$D$2)} -> #NAME? | H3: {=_xll.TR(H4,$D$2)} -> #NAME? | I3: {=_xll.TR(I4,$D$2)} -> #NAME? | J3: {=_xll.TR(J4,$D$2)} -> #NAME? | K3: {=_xll.TR(K4,$D$2)} -> #NAME? | L3: {=_xll.TR(L4,$D$2)} -> #NAME? | ... BN3: {=_xll.TR(BN4,$D$2)} -> #NAME?
A4: {=_xll.TR(A3,)} -> #NAME? | C4: COD | E4: SM-POGR-BR | F4: SM-OEPR-BR | G4: SM-NOPR-BR | H4: SM-TRIM-BR | I4: SM-CHAP-BR | J4: SM-CAMP-BR | K4: SM-PASSO-BR | L4: SM-CAMGR-BR | M4: SM-RONDON-BR | N4: SM-RIOVERDE-BR | O4: SM-MOGIANA-BR | P4: SM-IJUI-BR | Q4: BO-SAOP-BR | R4: SB-GTRIM-BR | S4: SB-GSORR-BR | T4: SB-GSORO-BR | U4: SB-GROND-BR | V4: SB-GRIVE-BR | W4: SB-GPOGR-BR | X4: SB-GPAFU-BR | Y4: SB-GOEPR-BR | Z4: SB-GNOPR-BR | AA4: SB-GMOGI-BR | AB4: SB-GIJUI-BR | AC4: SB-GBARR-BR | AD4: SB-GBASL-BR | AE4: SB-WPAFU-BR | AF4: SB-WSORO-BR | AG4: SB-WSORR-BR | AH4: LEN-CACR-BR | AI4: LEN-CASS-BR | AJ4: LEN-ITRM-BR | AK4: LEN-NOGS-BR | AL4: LEN-ROND-BR | AM4: LEN-WBHAI-BR | AN4: LEAN-CASS-BR | AO4: LEN-WBATD-BR | AP4: LEAN-CCDI-BR | AQ4: LEAN-CCRS-BR | AR4: LEAN-ITRM-BR | AS4: LEAN-NOGS-BR | AT4: LEAN-PANTL-BR | AU4: LEAN-PARA-BR | AV4: LEAN-RGND-BR | AW4: LEAN-RGNDS-BR | AX4: SB-WRIVE-BR | AY4: LEAN-WOBHS-BR | AZ4: LEAN-RNDPLS-BR | BA4: SB-WROND-BR | BB4: SB-WPOGR-BR | BC4: SB-WOEPR-BR | BD4: SB-WNOPR-BR | BE4: SB-WMOGI-BR | BF4: SB-WTRIM-BR | BG4: SB-WIJUI-BR | BH4: SB-WBARR-BR | BI4: SB-GRCNR-BR | BJ4: SB-WBRCN-BR | BK4: SB-GDCGR-BR | BL4: SB-GDUMS-BR | BM4: SB-GCHAMS-BR | BN4: SB-GMRMS-BR
A5: SM-OEPR-BR | C5: =YEAR(D5)&MONTH(D5) -> 20264 | D5: 46140 | X5: 114.48 | Y5: 109.89 | AB5: 114.59 | AE5: 119.41 | BC5: 117.98 | BG5: 118.86
A6: SM-NOPR-BR | C6: =YEAR(D6)&MONTH(D6) -> 20264 | D6: 46139 | E6: 1892.51 | F6: 1842.05 | G6: 1826.98 | H6: 1743.75 | I6: 1746.04 | J6: 1713.32 | K6: 1700.51 | L6: 1649.97 | M6: 1616.05 | N6: 1597.81 | O6: 1705.37 | P6: 1733.06 | Q6: 6707.09 | R6: 108.04 | S6: 99.73 | T6: 111.54 | V6: 106.78 | W6: 112.94 | X6: 113.62 | Y6: 109.73 | Z6: 110.8 | AA6: 109.23 | AB6: 114.12 | AE6: 119.27 | AF6: 113.81 | AG6: 102.08 | AI6: 10 | AL6: 30 | AN6: 4512.15 | AO6: 45 | AP6: 4419.24 | AQ6: 4478.38 | AR6: 4346.18 | AS6: 4233.56 | AT6: 4475.84 | AU6: 4420.19 | AW6: 4386.82 | AX6: 112.69 | AY6: 4462.95 | AZ6: 4571.76 | BA6: 102.28 | BB6: 122.22 | BC6: 117.02 | BD6: 119.07 | BE6: 111.81 | BF6: 112.9 | BG6: 119.68 | BH6: 112.87 | BI6: 116.8 | BJ6: 123.52 | BK6: 104.17 | BL6: 103.93 | BN6: 104.34
A7: SM-TRIM-BR | C7: =YEAR(D7)&MONTH(D7) -> 20264 | D7: 46136 | E7: 1877.62 | F7: 1842.05 | G7: 1826.98 | H7: 1742.59 | I7: 1746.04 | J7: 1713.32 | K7: 1700.51 | L7: 1679.03 | M7: 1608.43 | N7: 1618.02 | O7: 1709.36 | P7: 1761.23 | Q7: 6792.54 | R7: 107.32 | S7: 99.67 | T7: 110.98 | V7: 106.7 | W7: 111.94 | X7: 113.73 | Y7: 109.75 | Z7: 110 | AA7: 109.24 | AB7: 114.12 | AE7: 119.27 | AF7: 114.45 | AG7: 101.6 | AI7: 10 | AL7: 30 | AN7: 4482.93 | AO7: 37.5 | AP7: 4424.54 | AQ7: 4478.38 | AR7: 4367.17 | AT7: 4519.48 | AU7: 4349 | AW7: 4371.87 | AX7: 112.6 | AY7: 4432.59 | AZ7: 4571.76 | BA7: 102.05 | BB7: 121.85 | BC7: 117.82 | BD7: 118.46 | BE7: 112.69 | BF7: 111.03 | BG7: 119.48 | BH7: 112.33 | BI7: 116.8 | BJ7: 123.52 | BK7: 104.17 | BL7: 103.93 | BN7: 104.34
A8: SM-CHAP-BR | C8: =YEAR(D8)&MONTH(D8) -> 20264 | D8: 46135 | E8: 1875.97 | F8: 1842.05 | G8: 1826.98 | H8: 1745.06 | I8: 1736.16 | J8: 1719.98 | K8: 1700.51 | L8: 1679.03 | M8: 1608.43 | N8: 1620.34 | O8: 1711.03 | P8: 1761.23 | Q8: 6681.2 | R8: 106.61 | S8: 97.06 | T8: 110.86 | V8: 106.52 | W8: 112.34 | X8: 114.73 | Y8: 108.95 | Z8: 110 | AA8: 108.06 | AB8: 115.32 | AE8: 119.7 | AF8: 113.5 | AG8: 100.48 | AI8: 10 | AN8: 4513.54 | AO8: 37.5 | AP8: 4374.45 | AR8: 4367.17 | AS8: 4422.47 | AT8: 4534.95 | AW8: 4371.87 | AX8: 112.12 | AY8: 4436.24 | BA8: 97.47 | BB8: 121.97 | BC8: 116.5 | BD8: 118.28 | BE8: 111 | BF8: 110.48 | BG8: 120.67 | BH8: 111.33 | BI8: 116.83 | BJ8: 123.5 | BK8: 103.17 | BL8: 103.43 | BN8: 103.34
A9: SM-CAMP-BR | C9: =YEAR(D9)&MONTH(D9) -> 20264 | D9: 46134 | E9: 1882.58 | F9: 1842.05 | G9: 1826.98 | I9: 1759.87 | J9: 1719.98 | K9: 1700.51 | L9: 1679.03 | M9: 1597.05 | N9: 1640.63 | O9: 1685.13 | P9: 1761.23 | Q9: 6681.2 | R9: 105.77 | S9: 97.04 | T9: 111.43 | V9: 106.79 | W9: 112.74 | X9: 115.39 | Y9: 109.73 | Z9: 110.7 | AA9: 107.58 | AB9: 115.52 | AE9: 120.13 | AF9: 114.15 | AG9: 100.98 | AI9: 12.5 | AN9: 4525.95 | AO9: 30 | AP9: 4374.45 | AR9: 4391.16 | AS9: 4422.47 | AT9: 4458.7 | AU9: 4407.29 | AW9: 4371.87 | AX9: 111.81 | AY9: 4428.61 | BA9: 97.46 | BB9: 121.62 | BC9: 116.56 | BD9: 118.33 | BE9: 110.79 | BF9: 108.12 | BG9: 120.67 | BH9: 111.33 | BI9: 116.68 | BJ9: 123.48 | BK9: 104.17 | BL9: 103.93 | BN9: 104.34
A10: SM-PASSO-BR | C10: =YEAR(D10)&MONTH(D10) -> 20264 | D10: 46132 | E10: 1851.69 | F10: 1811.97 | G10: 1810.69 | I10: 1757.87 | J10: 1725.88 | K10: 1680.51 | L10: 1655.06 | M10: 1610.26 | N10: 1641.03 | O10: 1680.38 | P10: 1749.99 | Q10: 6679.37 | R10: 105.09 | S10: 95.99 | T10: 110.97 | V10: 106.78 | W10: 111.94 | X10: 115.84 | Y10: 108.99 | Z10: 109.7 | AA10: 106.3 | AB10: 116.12 | AE10: 120.41 | AF10: 114.53 | AG10: 100.42 | AI10: 30 | AN10: 4461.42 | AO10: 30 | AP10: 4336.67 | AQ10: 4312.84 | AR10: 4445.82 | AS10: 4478.13 | AT10: 4422.69 | AU10: 4407.29 | AX10: 111.75 | AY10: 4420.6 | AZ10: 4452.83 | BA10: 94.13 | BB10: 121.67 | BC10: 116.16 | BD10: 117.94 | BE10: 110.68 | BF10: 109.15 | BG10: 120.67 | BH10: 112.23 | BI10: 116.68 | BJ10: 123.44 | BK10: 103.17 | BL10: 103.43 | BN10: 103.34
A11: SM-CAMGR-BR | C11: =YEAR(D11)&MONTH(D11) -> 20264 | D11: 46129 | E11: 1849.21 | F11: 1811.97 | G11: 1814.02 | I11: 1757.87 | J11: 1725.88 | K11: 1680.51 | L11: 1681.83 | M11: 1612.08 | N11: 1643.95 | O11: 1680.26 | P11: 1749.99 | Q11: 6812.71 | R11: 106.5 | S11: 95.85 | T11: 110.96 | V11: 106.99 | W11: 112.14 | X11: 116.73 | Y11: 109.44 | Z11: 109.9 | AA11: 106.94 | AB11: 117.02 | AE11: 120.69 | AF11: 114.53 | AG11: 100.42 | AI11: 30 | AN11: 4485.28 | AO11: 30 | AP11: 4336.67 | AQ11: 4312.84 | AR11: 4504.06 | AS11: 4508.17 | AT11: 4371.48 | AU11: 4407.29 | AV11: 30 | AW11: 4399.48 | AX11: 110.98 | AY11: 4381.58 | AZ11: 4518.61 | BA11: 96.31 | BB11: 121.86 | BC11: 115.5 | BD11: 118.45 | BE11: 110.85 | BF11: 109.02 | BG11: 120.87 | BH11: 112 | BI11: 116.68 | BJ11: 123.38 | BK11: 103.17 | BL11: 104.18 | BN11: 103.34
A12: SM-RONDON-BR | C12: =YEAR(D12)&MONTH(D12) -> 20264 | D12: 46128 | E12: 1849.21 | F12: 1803.76 | G12: 1814.02 | H12: 1746.11 | I12: 1749.97 | J12: 1725.88 | K12: 1718.44 | L12: 1654.08 | M12: 1638.41 | N12: 1643.95 | O12: 1678.95 | P12: 1757.49 | Q12: 6689.75 | R12: 107.32 | S12: 95.44 | T12: 110.96 | V12: 107.48 | W12: 112.14 | X12: 117.39 | Y12: 110.03 | Z12: 109.9 | AA12: 107.41 | AB12: 117.91 | AE12: 121.12 | AF12: 114.07 | AG12: 100.04 | AI12: 30 | AN12: 4511 | AO12: 30 | AP12: 4445.63 | AQ12: 4312.84 | AR12: 4504.06 | AS12: 4559.6 | AT12: 4371.48 | AU12: 4407.29 | AW12: 4406.76 | AX12: 110.41 | AY12: 4385.46 | AZ12: 4518.61 | BA12: 102.83 | BB12: 121.93 | BC12: 116 | BD12: 117.92 | BE12: 111.07 | BF12: 108.74 | BG12: 122.06 | BH12: 111.33 | BI12: 116.8 | BJ12: 123.34 | BK12: 104.17 | BL12: 104.93 | BN12: 104.34
A13: SM-RIOVERDE-BR | C13: =YEAR(D13)&MONTH(D13) -> 20264 | D13: 46127 | E13: 1823.33 | F13: 1770.19 | G13: 1803.46 | H13: 1743.23 | I13: 1761.97 | J13: 1725.88 | K13: 1730.44 | L13: 1654.08 | M13: 1604.23 | N13: 1642.99 | O13: 1678.95 | P13: 1762.49 | Q13: 6781.2 | R13: 106.47 | S13: 95.42 | T13: 111.35 | V13: 107.47 | W13: 112.14 | X13: 117.39 | Y13: 110.5 | Z13: 109.9 | AA13: 107.12 | AB13: 118.29 | AE13: 121.9 | AF13: 114.05 | AG13: 100.03 | AN13: 4522.27 | AO13: 30 | AP13: 4474.58 | AQ13: 4312.84 | AR13: 4485.72 | AS13: 4486.35 | AT13: 4371.48 | AU13: 4456.2 | AW13: 4373.88 | AX13: 109.5 | AY13: 4407.2 | AZ13: 4518.61 | BA13: 106.91 | BB13: 121.76 | BC13: 116.3 | BD13: 119.13 | BE13: 110.45 | BF13: 107.94 | BG13: 122.76 | BH13: 111.33 | BI13: 117.18 | BJ13: 123.34 | BK13: 105.17 | BL13: 105.43 | BN13: 105.34
A14: SM-MOGIANA-BR | C14: =YEAR(D14)&MONTH(D14) -> 20264 | D14: 46126 | E14: 1823.33 | F14: 1770.19 | G14: 1803.46 | H14: 1737.47 | I14: 1756.04 | J14: 1739.07 | K14: 1730.44 | L14: 1682.97 | M14: 1615.63 | N14: 1606.65 | O14: 1709.39 | P14: 1731.03 | Q14: 6981.2 | R14: 106.46 | S14: 95.4 | T14: 111.7 | V14: 107.41 | W14: 113.54 | X14: 118 | Y14: 111.05 | Z14: 111.7 | AA14: 107.18 | AB14: 119.41 | AE14: 122.11 | AF14: 113.53 | AG14: 100.03 | AN14: 4540.98 | AO14: 30 | AP14: 4478.21 | AR14: 4371.87 | AS14: 4514.31 | AT14: 4401.5 | AU14: 4456.2 | AV14: 30 | AW14: 4388.41 | AX14: 110.92 | AY14: 4407.2 | AZ14: 4518.61 | BA14: 106.16 | BB14: 121.59 | BC14: 116.37 | BD14: 118.31 | BE14: 110.42 | BF14: 109.24 | BG14: 124.56 | BH14: 112 | BI14: 117.93 | BJ14: 123.12 | BK14: 104.17 | BL14: 104.93 | BN14: 104.34
A15: SM-IJUI-BR | C15: =YEAR(D15)&MONTH(D15) -> 20264 | D15: 46125 | E15: 1850.09 | F15: 1774.28 | G15: 1797.88 | H15: 1716.06 | I15: 1746.04 | J15: 1753.49 | K15: 1718.44 | L15: 1682.97 | M15: 1569.36 | N15: 1588.54 | O15: 1714.59 | P15: 1762.49 | Q15: 7005.9 | R15: 108.37 | S15: 95.88 | T15: 113.34 | V15: 108.17 | W15: 114.34 | X15: 118.56 | Y15: 111.95 | Z15: 112.69 | AA15: 108.49 | AB15: 120.01 | AE15: 122.47 | AF15: 112.48 | AG15: 99.45 | AN15: 4560.76 | AP15: 4436.25 | AQ15: 4424.16 | AR15: 4338.98 | AS15: 4486.61 | AT15: 4439.34 | AU15: 4456.2 | AV15: 30 | AW15: 4411.64 | AX15: 111.08 | AY15: 4414.12 | AZ15: 4475.6 | BA15: 106.14 | BB15: 121.66 | BC15: 116.72 | BD15: 118.45 | BE15: 111.52 | BF15: 110.93 | BG15: 124.56 | BH15: 112.67 | BI15: 118.8 | BJ15: 123.1 | BK15: 106.17 | BL15: 106.43 | BN15: 106.33
A16: BO-SAOP-BR | C16: =YEAR(D16)&MONTH(D16) -> 20264 | D16: 46122 | E16: 1887.55 | F16: 1842.05 | G16: 1830.7 | H16: 1696.3 | I16: 1736.16 | J16: 1786.55 | K16: 1726.39 | L16: 1640.54 | M16: 1556.03 | N16: 1589.09 | O16: 1740.47 | P16: 1767.46 | Q16: 7005.9 | R16: 108.37 | S16: 96.57 | T16: 113.86 | V16: 108.34 | W16: 114.54 | X16: 118.45 | Y16: 111.95 | Z16: 112.89 | AA16: 108.55 | AB16: 119.41 | AE16: 122.61 | AF16: 113.69 | AG16: 102.1 | AN16: 4545.22 | AP16: 4436.25 | AQ16: 4416.3 | AR16: 4338.98 | AS16: 4436.99 | AT16: 4498.37 | AU16: 4407.29 | AV16: 30 | AW16: 4396.41 | AX16: 111.02 | AY16: 4423.99 | AZ16: 4431.74 | BA16: 107.73 | BB16: 122.36 | BC16: 116.72 | BD16: 118.88 | BE16: 112.02 | BF16: 111.77 | BG16: 124.16 | BH16: 112.67 | BI16: 118.8 | BJ16: 123.64 | BK16: 106.17 | BL16: 106.43 | BN16: 106.33
A17: SB-GTRIM-BR | C17: =YEAR(D17)&MONTH(D17) -> 20264 | D17: 46121 | E17: 1869.35 | F17: 1842.05 | G17: 1814.15 | H17: 1696.3 | I17: 1736.16 | J17: 1786.55 | K17: 1706.39 | L17: 1640.54 | M17: 1556.31 | N17: 1609.88 | O17: 1706.78 | P17: 1742.46 | Q17: 7005.9 | R17: 109.2 | S17: 97 | T17: 114.08 | V17: 108.62 | W17: 114.42 | X17: 118.56 | Y17: 111.95 | Z17: 112.89 | AA17: 108.98 | AB17: 119.41 | AE17: 122.89 | AF17: 112.5 | AG17: 102.36 | AN17: 4557.09 | AP17: 4440 | AQ17: 4416.3 | AR17: 4338.98 | AS17: 4436.99 | AT17: 4498.37 | AU17: 4407.29 | AV17: 30 | AW17: 4396.41 | AX17: 109.65 | AY17: 4423.99 | AZ17: 4431.74 | BA17: 107.1 | BB17: 122.87 | BC17: 117.15 | BD17: 120.15 | BE17: 111.83 | BF17: 111.8 | BG17: 124.16 | BH17: 113.2 | BI17: 118.8 | BJ17: 123.62 | BK17: 106.17 | BL17: 106.43 | BN17: 106.33
A18: SB-GSORR-BR | C18: =YEAR(D18)&MONTH(D18) -> 20264 | D18: 46120 | E18: 1866.04 | F18: 1842.05 | G18: 1822.98 | I18: 1736.16 | J18: 1786.55 | K18: 1706.39 | L18: 1640.54 | M18: 1543.28 | N18: 1609.88 | O18: 1757.94 | P18: 1742.46 | Q18: 7112.31 | R18: 109.86 | S18: 96.9 | T18: 113.93 | V18: 108.76 | W18: 114.67 | X18: 118.78 | Y18: 111.18 | Z18: 112.69 | AA18: 109.88 | AB18: 119.71 | AE18: 123.11 | AF18: 113.37 | AG18: 102.6 | AI18: 30 | AN18: 4587.39 | AP18: 4403 | AQ18: 4416.3 | AR18: 4339.82 | AS18: 4426.3 | AT18: 4498.37 | AU18: 4394.13 | AV18: 30 | AW18: 4412.5 | AX18: 110.33 | AY18: 4409.82 | AZ18: 4431.74 | BA18: 105.48 | BB18: 123.57 | BC18: 116.27 | BD18: 119.04 | BE18: 112.16 | BF18: 112.45 | BG18: 124.16 | BH18: 112.87 | BI18: 119.17 | BJ18: 123.4 | BK18: 106.17 | BL18: 106.43 | BN18: 106.33
A19: SB-GSORO-BR | C19: =YEAR(D19)&MONTH(D19) -> 20264 | D19: 46119 | E19: 1872.66 | F19: 1855.61 | G19: 1822.98 | I19: 1753.94 | J19: 1772.71 | K19: 1722.39 | L19: 1634.46 | M19: 1567.94 | N19: 1618.28 | O19: 1743.11 | P19: 1758.7 | Q19: 7089.24 | R19: 109.86 | S19: 97.38 | T19: 114.01 | V19: 109.17 | W19: 115.42 | X19: 119.44 | Y19: 112.95 | Z19: 113.69 | AA19: 109.88 | AB19: 120.31 | AE19: 123.39 | AF19: 115.25 | AG19: 103.01 | AI19: 30 | AN19: 4588.66 | AP19: 4378.75 | AQ19: 4416.3 | AR19: 4330.67 | AS19: 4426.3 | AT19: 4503.43 | AU19: 4394.13 | AV19: 30 | AW19: 4457.67 | AX19: 109.81 | AY19: 4409.82 | AZ19: 4431.74 | BA19: 105.45 | BB19: 124.21 | BC19: 118.19 | BD19: 120.17 | BE19: 112.99 | BF19: 113.41 | BG19: 124.16 | BH19: 115 | BI19: 119.29 | BJ19: 123.58 | BK19: 106.17 | BL19: 106.43 | BN19: 106.33
A20: SB-GROND-BR | C20: =YEAR(D20)&MONTH(D20) -> 20264 | D20: 46118 | E20: 1872.66 | F20: 1855.61 | G20: 1846.98 | H20: 1691.62 | I20: 1759.92 | J20: 1763.37 | K20: 1726.39 | L20: 1634.46 | M20: 1560.19 | N20: 1601.26 | O20: 1758.03 | P20: 1758.7 | Q20: 7028.69 | R20: 109.6 | S20: 97.49 | T20: 114.01 | V20: 108.99 | W20: 115.42 | X20: 120 | Y20: 112.83 | Z20: 113.69 | AA20: 110 | AB20: 119.9 | AE20: 123.67 | AF20: 115.26 | AG20: 102.57 | AI20: 30 | AN20: 4556.56 | AO20: 30 | AQ20: 4373.39 | AR20: 4341.51 | AS20: 4447.77 | AT20: 4439.32 | AU20: 4394.13 | AV20: 30 | AW20: 4457.53 | AX20: 108.16 | AY20: 4422.98 | AZ20: 4410.3 | BA20: 104.98 | BB20: 125.08 | BC20: 118.3 | BD20: 121.16 | BE20: 113.9 | BF20: 113.22 | BG20: 124.16 | BH20: 115 | BI20: 119.29 | BJ20: 123.56 | BK20: 106.84 | BL20: 106.68 | BN20: 107
A21: SB-GRIVE-BR | C21: =YEAR(D21)&MONTH(D21) -> 20264 | D21: 46114 | E21: 1870.93 | F21: 1855.61 | G21: 1846.98 | H21: 1695.45 | I21: 1759.92 | J21: 1770.04 | K21: 1720.99 | L21: 1613.64 | M21: 1543.9 | N21: 1601.26 | O21: 1762.03 | P21: 1754.95 | Q21: 7075.26 | R21: 109.93 | S21: 97.57 | T21: 113.99 | V21: 108.71 | W21: 115.17 | X21: 119.44 | Y21: 112.91 | Z21: 113.69 | AA21: 111.1 | AB21: 119.51 | AE21: 123.11 | AF21: 113.47 | AG21: 102.37 | AI21: 30 | AN21: 4581.1 | AO21: 19 | AR21: 4341.51 | AS21: 4394.64 | AT21: 4513.86 | AU21: 4308.62 | AV21: 30 | AW21: 4481.86 | AX21: 107.7 | AY21: 4442.71 | AZ21: 4486.56 | BA21: 105.51 | BB21: 123.82 | BC21: 118.15 | BD21: 120.18 | BE21: 112.65 | BF21: 112.28 | BG21: 124.32 | BH21: 113.67 | BI21: 119.29 | BJ21: 122.49 | BK21: 106.84 | BL21: 106.68 | BN21: 107
A22: SB-GPOGR-BR | C22: =YEAR(D22)&MONTH(D22) -> 20264 | D22: 46113 | E22: 1859.42 | F22: 1855.61 | G22: 1841.05 | H22: 1706.92 | I22: 1759.92 | J22: 1786.7 | K22: 1726.39 | L22: 1644.46 | M22: 1543.9 | N22: 1612.79 | O22: 1794.02 | P22: 1758.7 | Q22: 7055.26 | R22: 110.76 | S22: 96.85 | T22: 113.4 | V22: 108.34 | W22: 114.67 | X22: 119.84 | Y22: 112.28 | Z22: 112.69 | AA22: 112.05 | AB22: 119.4 | AE22: 122.68 | AF22: 111.95 | AG22: 102.57 | AI22: 30 | AN22: 4557.25 | AO22: 19 | AP22: 4378.75 | AQ22: 4399.7 | AR22: 4301.03 | AS22: 4412.35 | AT22: 4475.47 | AV22: 30 | AW22: 4518.88 | AX22: 107.68 | AY22: 4442.71 | AZ22: 4457.89 | BA22: 103.65 | BB22: 124.28 | BC22: 117.64 | BD22: 121.02 | BE22: 113.23 | BF22: 113.11 | BG22: 124.16 | BH22: 113.67 | BI22: 119.29 | BJ22: 122.47 | BK22: 106.5 | BL22: 105.93 | BN22: 106.67
A23: SB-GPAFU-BR | C23: =YEAR(D23)&MONTH(D23) -> 20263 | D23: 46112 | E23: 1852.8 | F23: 1878.15 | G23: 1841.05 | H23: 1741.33 | I23: 1767.83 | J23: 1807.57 | K23: 1726.39 | L23: 1686.77 | M23: 1582.1 | N23: 1624.85 | O23: 1814.98 | P23: 1758.7 | Q23: 7055.26 | R23: 110.76 | S23: 97.51 | T23: 114.29 | V23: 110.51 | W23: 116.17 | X23: 118.94 | Y23: 113.83 | Z23: 114.59 | AA23: 111.72 | AB23: 119.56 | AE23: 122.68 | AF23: 113.99 | AG23: 102.63 | AI23: 25 | AN23: 4478.72 | AO23: 15.33 | AP23: 4378.75 | AQ23: 4399.7 | AR23: 4301.03 | AS23: 4405.6 | AT23: 4453.12 | AW23: 4554.03 | AX23: 105.59 | AY23: 4366.3 | AZ23: 4462.95 | BA23: 104.4 | BB23: 125.23 | BC23: 118.51 | BD23: 120.01 | BE23: 113.7 | BF23: 114.24 | BG23: 124.16 | BH23: 116.17 | BI23: 119.17 | BJ23: 122.53 | BK23: 107.17 | BL23: 108.4 | BN23: 107.33
A24: SB-GOEPR-BR | C24: =YEAR(D24)&MONTH(D24) -> 20263 | D24: 46111 | E24: 1846.19 | F24: 1878.15 | G24: 1846.98 | H24: 1741.33 | I24: 1783.83 | J24: 1809.08 | K24: 1726.39 | L24: 1686.77 | M24: 1584.36 | N24: 1625.62 | O24: 1809.99 | P24: 1771.2 | Q24: 7055.51 | R24: 110.11 | S24: 98.69 | T24: 114.36 | V24: 110.3 | W24: 116.42 | X24: 118.39 | Y24: 114.42 | Z24: 114.79 | AA24: 111.58 | AB24: 118.86 | AE24: 122.68 | AF24: 115.11 | AG24: 102.54 | AI24: 25 | AN24: 4478.72 | AO24: 8 | AP24: 4378.75 | AQ24: 4399.7 | AR24: 4291.42 | AS24: 4375.24 | AT24: 4414.24 | AU24: 4460.42 | AW24: 4473.07 | AX24: 107.48 | AY24: 4289.9 | AZ24: 4399.7 | BA24: 103.49 | BB24: 124.66 | BC24: 118.5 | BD24: 120.65 | BE24: 114.39 | BF24: 112.87 | BG24: 124.16 | BH24: 116.33 | BI24: 119.17 | BJ24: 122.51 | BK24: 107.17 | BL24: 108.4 | BN24: 107.33
A25: SB-GNOPR-BR | C25: =YEAR(D25)&MONTH(D25) -> 20263 | D25: 46108 | E25: 1859.42 | F25: 1878.15 | G25: 1846.98 | H25: 1748.66 | I25: 1781.83 | J25: 1824.87 | K25: 1720.99 | L25: 1710.67 | M25: 1574.67 | N25: 1639.07 | O25: 1782.51 | P25: 1774.95 | Q25: 7118.4 | R25: 110.11 | S25: 98.64 | T25: 115.7 | V25: 110.21 | W25: 118.17 | X25: 117.72 | Y25: 116.81 | Z25: 116.69 | AA25: 111.66 | AB25: 118.52 | AE25: 122.68 | AF25: 114.94 | AG25: 103.26 | AI25: 15 | AN25: 4439.84 | AP25: 4378.75 | AQ25: 4399.7 | AR25: 4291.42 | AS25: 4392.11 | AT25: 4367.82 | AU25: 4460.42 | AW25: 4473.07 | AY25: 4289.9 | AZ25: 4399.7 | BA25: 102.4 | BB25: 126.39 | BC25: 120.07 | BD25: 121.68 | BE25: 114.33 | BF25: 113.75 | BG25: 125.32 | BH25: 115.33 | BI25: 118.54 | BJ25: 121.86 | BK25: 110.16 | BL25: 110.4 | BN25: 110.33
A26: SB-GMOGI-BR | C26: =YEAR(D26)&MONTH(D26) -> 20263 | D26: 46107 | E26: 1856.11 | F26: 1881.74 | G26: 1846.98 | H26: 1742.33 | I26: 1775.9 | J26: 1824.12 | K26: 1717.7 | L26: 1716.09 | M26: 1568.63 | N26: 1640.62 | O26: 1786.26 | P26: 1774.95 | Q26: 6907.49 | R26: 110.11 | S26: 98.83 | T26: 115.87 | V26: 109.94 | W26: 117.67 | X26: 118.05 | Y26: 114.77 | Z26: 116.28 | AA26: 111.65 | AB26: 117.96 | AE26: 123.49 | AF26: 115.97 | AG26: 103.07 | AI26: 15 | AN26: 4383.47 | AP26: 4378.75 | AQ26: 4399.7 | AR26: 4291.21 | AS26: 4392.11 | AT26: 4367.82 | AU26: 4460.42 | AW26: 4473.07 | AY26: 4289.9 | AZ26: 4399.7 | BA26: 102.04 | BB26: 126.01 | BC26: 119.66 | BD26: 121.14 | BE26: 114.79 | BF26: 113.36 | BG26: 125.82 | BH26: 116 | BI26: 118.54 | BJ26: 121.64 | BK26: 109.17 | BL26: 108.73 | BN26: 109.33
A27: SB-GIJUI-BR | C27: =YEAR(D27)&MONTH(D27) -> 20263 | D27: 46106 | E27: 1862.73 | F27: 1881.74 | G27: 1846.98 | H27: 1776.42 | I27: 1775.9 | J27: 1824.12 | K27: 1744.42 | L27: 1713.84 | M27: 1571.66 | N27: 1659.25 | O27: 1797 | P27: 1769.1 | Q27: 6845.12 | R27: 108.37 | S27: 98.81 | T27: 114.76 | V27: 109.79 | W27: 116.92 | X27: 117.17 | Y27: 114.55 | Z27: 115.49 | AA27: 110.88 | AB27: 117.74 | AE27: 122.25 | AF27: 115.93 | AG27: 102.21 | AI27: 15 | AN27: 4398.84 | AP27: 4400.17 | AQ27: 4399.7 | AR27: 4288.76 | AS27: 4351.63 | AT27: 4367.82 | AU27: 4460.42 | AW27: 4473.07 | AY27: 4289.9 | AZ27: 4427.53 | BA27: 99.75 | BB27: 125.6 | BC27: 118.27 | BD27: 120.06 | BE27: 113.54 | BF27: 111.38 | BG27: 125.36 | BH27: 116 | BI27: 118.54 | BJ27: 121.62 | BK27: 108.17 | BL27: 108.07 | BN27: 108.33
A28: SB-GBARR-BR | C28: =YEAR(D28)&MONTH(D28) -> 20263 | D28: 46105 | E28: 1879.28 | F28: 1881.74 | G28: 1846.98 | H28: 1772.92 | I28: 1756.14 | J28: 1789.6 | K28: 1744.42 | L28: 1721.57 | M28: 1570.1 | N28: 1688.48 | O28: 1769.01 | P28: 1775.71 | Q28: 6953.38 | R28: 108.37 | S28: 97.23 | T28: 115.76 | V28: 109.42 | W28: 116.92 | X28: 117.74 | Y28: 114.02 | Z28: 115.69 | AA28: 110.42 | AB28: 118.17 | AE28: 122.39 | AF28: 116.36 | AG28: 101.92 | AN28: 4404.57 | AO28: 30 | AP28: 4400.17 | AQ28: 4399.7 | AR28: 4297.99 | AS28: 4346.57 | AT28: 4450.63 | AU28: 4470.82 | AW28: 4432.59 | AZ28: 4424.9 | BA28: 96.67 | BB28: 124.52 | BC28: 117.85 | BD28: 120.14 | BE28: 114.15 | BF28: 111.88 | BG28: 125.76 | BH28: 115.67 | BI28: 119.39 | BJ28: 121.6 | BK28: 108.17 | BL28: 108.07 | BN28: 108.33
A29: SB-GBASL-BR | C29: =YEAR(D29)&MONTH(D29) -> 20263 | D29: 46104 | E29: 1902.44 | F29: 1881.74 | G29: 1832.98 | I29: 1760.28 | J29: 1772.87 | K29: 1740.42 | L29: 1718.1 | N29: 1688.48 | O29: 1785.21 | P29: 1770.71 | Q29: 6732.24 | R29: 108.37 | S29: 97.22 | T29: 115.63 | V29: 110.14 | W29: 117.67 | X29: 117.67 | Y29: 115.26 | Z29: 116.29 | AA29: 110.17 | AB29: 118.32 | AE29: 122.39 | AF29: 116.74 | AG29: 101.92 | AN29: 4404.57 | AO29: 30 | AP29: 4400.17 | AQ29: 4399.7 | AR29: 4290.91 | AS29: 4388.06 | AT29: 4395.52 | AU29: 4416.78 | AW29: 4283.84 | AY29: 4245.37 | AZ29: 4380.98 | BA29: 100.14 | BB29: 124.09 | BC29: 118.19 | BD29: 119.61 | BE29: 111.07 | BF29: 111.88 | BG29: 125.76 | BH29: 115.67 | BI29: 118.54 | BJ29: 121.58 | BK29: 108.17 | BL29: 108.07 | BN29: 108.33
A30: SB-WPAFU-BR | C30: =YEAR(D30)&MONTH(D30) -> 20263 | D30: 46101 | E30: 1869.5 | F30: 1845.81 | G30: 1807.29 | H30: 1700.93 | I30: 1736.64 | J30: 1789.34 | K30: 1740.42 | L30: 1705.75 | N30: 1719.6 | O30: 1785.21 | P30: 1775.71 | Q30: 6857.24 | R30: 108.78 | S30: 97.44 | T30: 115.24 | V30: 109.13 | W30: 116.67 | X30: 118.19 | Y30: 114.14 | Z30: 115.69 | AA30: 110.85 | AB30: 118.42 | AE30: 122.82 | AF30: 116.74 | AG30: 100.37 | AI30: 30 | AN30: 4434.27 | AO30: 30 | AP30: 4400.17 | AQ30: 4399.7 | AR30: 4290.91 | AS30: 4388.06 | AT30: 4375.8 | AU30: 4380.98 | AW30: 4251.87 | AY30: 4245.37 | AZ30: 4380.98 | BA30: 100.74 | BB30: 124.53 | BC30: 119.1 | BD30: 120.88 | BE30: 111.4 | BF30: 111.09 | BG30: 126.16 | BH30: 113.33 | BI30: 118.54 | BJ30: 121.72 | BK30: 108.17 | BL30: 108.07 | BN30: 108.23
A31: SB-WSORO-BR | C31: =YEAR(D31)&MONTH(D31) -> 20263 | D31: 46100 | E31: 1875.94 | F31: 1833.01 | G31: 1791.16 | H31: 1712.16 | I31: 1729.07 | J31: 1780.15 | K31: 1700.38 | L31: 1705.6 | N31: 1715.3 | O31: 1775.11 | P31: 1753.16 | Q31: 6706.8 | R31: 108.7 | S31: 96.03 | T31: 114.45 | V31: 107.62 | W31: 115.42 | X31: 117.33 | Y31: 113.88 | Z31: 114.68 | AA31: 110.03 | AB31: 117.81 | AE31: 122.38 | AF31: 116.06 | AG31: 99.49 | AI31: 30 | AN31: 4406.91 | AO31: 30 | AP31: 4400.17 | AR31: 4291.73 | AS31: 4391.26 | AT31: 4376.25 | AU31: 4381.81 | AW31: 4252.68 | AY31: 4246.18 | AZ31: 4381.81 | BA31: 100.39 | BB31: 123.33 | BC31: 118.75 | BD31: 120.29 | BE31: 111.38 | BF31: 111.08 | BG31: 125.55 | BH31: 114.33 | BI31: 118.66 | BJ31: 121.67 | BK31: 107.17 | BL31: 107.4 | BN31: 107.33
A32: SB-WSORR-BR | C32: =YEAR(D32)&MONTH(D32) -> 20263 | D32: 46099 | E32: 1836.23 | F32: 1841.99 | G32: 1781.28 | H32: 1718.15 | I32: 1740.92 | J32: 1780.15 | K32: 1700.38 | L32: 1705.6 | N32: 1671.95 | O32: 1798.09 | P32: 1753.16 | Q32: 6656.9 | R32: 105.72 | S32: 94.74 | T32: 113.74 | V32: 107.11 | W32: 114.17 | X32: 117.33 | Y32: 112.95 | Z32: 113.69 | AA32: 107.79 | AB32: 118.01 | AE32: 122.38 | AF32: 114.02 | AG32: 99.06 | AI32: 30 | AN32: 4406.91 | AO32: 30 | AP32: 4412 | AQ32: 4448.62 | AR32: 4291.73 | AS32: 4362.58 | AT32: 4376.25 | AU32: 4381.81 | AW32: 4252.68 | AY32: 4246.18 | AZ32: 4381.81 | BA32: 100.37 | BB32: 123.1 | BC32: 116.27 | BD32: 118.69 | BE32: 109.04 | BF32: 108.04 | BG32: 125.55 | BH32: 114.33 | BI32: 118.66 | BJ32: 121.65 | BK32: 106.17 | BL32: 106.4 | BN32: 106.33
A33: LEN-CACR-BR | C33: =YEAR(D33)&MONTH(D33) -> 20263 | D33: 46098 | E33: 1832.92 | F33: 1831.28 | G33: 1775.28 | H33: 1736.11 | I33: 1744.87 | J33: 1788.49 | K33: 1712.38 | L33: 1705.6 | N33: 1674.95 | O33: 1808.09 | P33: 1753.16 | Q33: 6706.9 | R33: 105.64 | S33: 94.25 | T33: 113.96 | V33: 108.78 | W33: 114.17 | X33: 118.29 | Y33: 113.35 | Z33: 113.88 | AA33: 109.51 | AB33: 118.66 | AE33: 123.52 | AF33: 112.81 | AG33: 98.4 | AI33: 30 | AN33: 4373.04 | AO33: 30 | AP33: 4412 | AQ33: 4448.62 | AR33: 4212.27 | AS33: 4401.04 | AT33: 4323.17 | AU33: 4357.42 | AW33: 4252.68 | AX33: 110.25 | AY33: 4246.18 | AZ33: 4256.3 | BA33: 96.03 | BB33: 122.18 | BC33: 116.95 | BD33: 118.74 | BE33: 108.12 | BF33: 107.68 | BG33: 125.55 | BH33: 114.33 | BI33: 119.64 | BJ33: 121.86 | BK33: 106.17 | BL33: 106.4 | BN33: 106.33
A34: LEN-CASS-BR | C34: =YEAR(D34)&MONTH(D34) -> 20263 | D34: 46097 | E34: 1856.08 | F34: 1841.99 | G34: 1775.28 | H34: 1723.83 | I34: 1764.87 | J34: 1803.86 | K34: 1720.38 | L34: 1725.96 | N34: 1637.92 | O34: 1790.07 | P34: 1766.89 | Q34: 6706.9 | R34: 106.83 | S34: 96.78 | T34: 114.74 | V34: 110.89 | W34: 115.92 | X34: 119.22 | Y34: 114.74 | Z34: 115.08 | AA34: 109.93 | AB34: 118.86 | AE34: 123.36 | AF34: 113.96 | AG34: 100.31 | AI34: 30 | AN34: 4373.04 | AP34: 4365 | AQ34: 4448.62 | AR34: 4212.65 | AS34: 4359.21 | AT34: 4352.46 | AU34: 4304.93 | AV34: 36.67 | AW34: 4276.48 | AX34: 110.25 | AY34: 4322.28 | AZ34: 4256.3 | BA34: 102.03 | BB34: 122.38 | BC34: 118.92 | BD34: 120.11 | BE34: 108.97 | BF34: 108.8 | BG34: 125.55 | BH34: 114.33 | BI34: 120.16 | BJ34: 121.84 | BK34: 107.17 | BL34: 107.73 | BN34: 107.33
A35: LEN-ITRM-BR | C35: =YEAR(D35)&MONTH(D35) -> 20263 | D35: 46094 | E35: 1864.33 | F35: 1833.01 | G35: 1775.28 | H35: 1723.53 | I35: 1746.9 | J35: 1808.86 | K35: 1720.33 | L35: 1725.96 | N35: 1652.34 | O35: 1810.07 | P35: 1771.86 | Q35: 6631.9 | R35: 109.03 | S35: 96.89 | T35: 115.99 | V35: 110.92 | W35: 117.17 | X35: 119.77 | Y35: 115.75 | Z35: 116.68 | AA35: 110.88 | AB35: 119.66 | AE35: 124.28 | AF35: 114.94 | AG35: 102.29 | AN35: 4365.11 | AP35: 4365 | AQ35: 4448.62 | AR35: 4212.65 | AS35: 4353.09 | AT35: 4352.46 | AU35: 4321.92 | AV35: 36.67 | AW35: 4279.14 | AX35: 109.13 | AY35: 4322.28 | AZ35: 4256.3 | BA35: 101.96 | BB35: 124.06 | BC35: 119.15 | BD35: 121.02 | BE35: 111.68 | BF35: 112.13 | BG35: 126.35 | BH35: 116 | BI35: 120.16 | BJ35: 122.57 | BK35: 109.16 | BL35: 108.73 | BN35: 109.33
A36: LEN-NOGS-BR | C36: =YEAR(D36)&MONTH(D36) -> 20263 | D36: 46093 | E36: 1867.64 | F36: 1833.01 | G36: 1781.21 | H36: 1722.61 | I36: 1746.9 | J36: 1785.53 | K36: 1720.33 | L36: 1701.26 | N36: 1650.52 | O36: 1810.07 | P36: 1771.86 | Q36: 6556.9 | R36: 110.02 | S36: 97.16 | T36: 115.63 | V36: 110.77 | W36: 115.67 | X36: 119.33 | Y36: 114.43 | Z36: 115.48 | AA36: 112.03 | AB36: 118.86 | AE36: 123.9 | AF36: 115.61 | AG36: 102.37 | AN36: 4330.19 | AP36: 4365 | AQ36: 4448.62 | AR36: 4212.65 | AS36: 4353.09 | AT36: 4352.46 | AU36: 4310.26 | AV36: 36.67 | AW36: 4279.14 | AX36: 107.03 | AY36: 4322.28 | AZ36: 4256.3 | BA36: 104.35 | BB36: 122.6 | BC36: 119.11 | BD36: 120.8 | BE36: 113.62 | BF36: 112.69 | BG36: 125.95 | BH36: 117 | BI36: 120.16 | BJ36: 122.55 | BK36: 108.5 | BL36: 108.07 | BN36: 108.67
A37: LEN-ROND-BR | C37: =YEAR(D37)&MONTH(D37) -> 20263 | D37: 46092 | E37: 1849.47 | F37: 1833.01 | G37: 1781.21 | H37: 1729.74 | I37: 1750.85 | J37: 1785.53 | K37: 1720.33 | L37: 1701.26 | N37: 1640.25 | O37: 1810.07 | P37: 1771.86 | Q37: 6556.9 | R37: 109.52 | S37: 96.86 | T37: 114.63 | V37: 110.68 | W37: 115.67 | X37: 118.83 | Y37: 113.94 | Z37: 114.68 | AA37: 111.51 | AB37: 118.66 | AE37: 123.26 | AF37: 115.57 | AG37: 100.76 | AN37: 4330.19 | AP37: 4309 | AR37: 4255.79 | AS37: 4353.09 | AT37: 4352.46 | AU37: 4317.57 | AV37: 35 | AW37: 4271.04 | AX37: 110.28 | AY37: 4322.28 | AZ37: 4256.3 | BA37: 104.33 | BB37: 122.6 | BC37: 117.95 | BD37: 120.39 | BE37: 113.59 | BF37: 111.47 | BG37: 126.14 | BH37: 117 | BI37: 120.16 | BJ37: 122.53 | BK37: 107.17 | BL37: 107.4 | BN37: 107.33
A38: LEN-WBHAI-BR | C38: =YEAR(D38)&MONTH(D38) -> 20263 | D38: 46091 | E38: 1872.75 | F38: 1842.1 | G38: 1801.21 | H38: 1729.74 | I38: 1750.85 | J38: 1819.43 | K38: 1724.33 | L38: 1711.14 | N38: 1652.96 | O38: 1826.55 | P38: 1764.36 | Q38: 6581.6 | R38: 109.45 | S38: 97.09 | T38: 114.62 | V38: 110.5 | W38: 116.39 | X38: 118.89 | Y38: 114.01 | Z38: 114.68 | AA38: 111.51 | AB38: 118.96 | AE38: 123.2 | AF38: 115.45 | AG38: 100.79 | AN38: 4283.63 | AP38: 4300 | AR38: 4251.24 | AS38: 4324.26 | AT38: 4327.15 | AU38: 4303.74 | AV38: 35 | AW38: 4271.04 | AX38: 111.23 | AY38: 4322.28 | BA38: 105.22 | BB38: 123.9 | BC38: 118.14 | BD38: 119.15 | BE38: 113.57 | BF38: 111.47 | BG38: 125.74 | BH38: 115.67 | BI38: 119.79 | BJ38: 122.51 | BK38: 107.17 | BL38: 107.4 | BN38: 107.33
A39: LEAN-CASS-BR | C39: =YEAR(D39)&MONTH(D39) -> 20263 | D39: 46090 | E39: 1872.75 | F39: 1842.1 | G39: 1801.21 | H39: 1746.47 | I39: 1750.85 | J39: 1825.6 | K39: 1717.66 | L39: 1729.86 | N39: 1661.7 | O39: 1829.84 | P39: 1754.9 | Q39: 6565.43 | R39: 111.26 | S39: 98.79 | T39: 114.79 | V39: 110.62 | W39: 116.22 | X39: 119.5 | Y39: 115.94 | Z39: 115.28 | AA39: 112.68 | AB39: 118.85 | AE39: 123.66 | AF39: 115.45 | AG39: 102.62 | AN39: 4306.26 | AP39: 4300 | AR39: 4251.24 | AS39: 4324.26 | AT39: 4347.44 | AU39: 4304.88 | AV39: 30 | AW39: 4278.51 | AX39: 111.53 | AY39: 4331.58 | AZ39: 4268.78 | BA39: 105.18 | BB39: 123.5 | BC39: 119.02 | BD39: 120.01 | BE39: 114.47 | BF39: 111.92 | BG39: 126.06 | BH39: 110.6 | BI39: 118.91 | BJ39: 122.49 | BK39: 107.17 | BL39: 107.4 | BN39: 107.33
A40: LEN-WBATD-BR | C40: =YEAR(D40)&MONTH(D40) -> 20263 | D40: 46087 | E40: 1851.24 | F40: 1851.08 | G40: 1811.21 | H40: 1723.05 | I40: 1770.75 | J40: 1825.6 | K40: 1754.18 | L40: 1729.86 | N40: 1665.02 | O40: 1791.45 | P40: 1754.38 | Q40: 6425.19 | R40: 111.66 | S40: 97.01 | T40: 115.68 | V40: 110.45 | W40: 117.22 | X40: 118.22 | Y40: 115.68 | Z40: 116.58 | AA40: 113.73 | AB40: 118.12 | AE40: 123.16 | AF40: 115.16 | AG40: 101.63 | AH40: 30 | AN40: 4317.04 | AP40: 4300 | AQ40: 4355.08 | AR40: 4251.24 | AT40: 4347.44 | AU40: 4301 | AV40: 30 | AW40: 4278.51 | AX40: 111.78 | AY40: 4331.58 | AZ40: 4308.68 | BA40: 105.13 | BB40: 124.12 | BC40: 118.89 | BD40: 120.86 | BE40: 114.47 | BF40: 114.24 | BG40: 125.81 | BH40: 114.17 | BI40: 118.41 | BJ40: 121.84 | BK40: 108.83 | BL40: 108.4 | BN40: 109
...

Sheet Modelo Crushing Margin LIQ
B1: fonte Abiove | F1: Versus Paridade de Exportação | G1: =AVERAGE(G3:G65) -> #REF! | H1: =AVERAGE(H3:H65) -> #REF! | I1: =AVERAGE(I3:I65) -> #REF! | J1: =AVERAGE(J3:J65) -> #REF! | K1: =AVERAGE(K3:K65) -> #REF! | L1: =AVERAGE(L3:L65) -> #REF! | M1: =AVERAGE(M3:M65) -> #REF! | Q1: Versus Disponivel | R1: =AVERAGE(R3:R65) -> #REF! | S1: =AVERAGE(S3:S65) -> #REF! | X1: =AVERAGE(X3:X65) -> #REF!
B2: Teor Oleo | C2: 0.208 | E2: ANO | F2: Data | G2: Sorriso | H2: Rondonopolis | I2: Cascavel | J2: Londrina | K2: Ijui | L2: Passo Fundo | M2: LRV | Q2: Data | R2: Sorriso | S2: Rondonopolis | T2: Cascavel | U2: Londrina | V2: Ijui | W2: Passo Fundo | X2: LRV | AL2: LRV
B3: Teor Farelo | C3: 0.75 | E3: =YEAR(F3) -> 2021 | F3: =+'Modelo Soja'!BA3 -> 44197 | G3: =+(('Modelo Farelo'!AB3*(1+$C$8))*$C$3+('Modelo Oleo'!AA3*(1))*$C$2)-('Modelo Soja'!AT3/60*1000)-$C$6 -> #REF! | H3: =+(('Modelo Farelo'!AC3*(1+$C$8))*$C$3+('Modelo Oleo'!AB3*(1))*$C$2)-('Modelo Soja'!AU3/60*1000)-$C$6 -> #REF! | I3: =+(('Modelo Farelo'!AD3*(1+$C$8))*$C$3+('Modelo Oleo'!AC3*(1))*$C$2)-('Modelo Soja'!AV3/60*1000)-$C$6 -> #REF! | J3: =+(('Modelo Farelo'!AE3*(1+$C$8))*($C$3+1%)+('Modelo Oleo'!AD3*(1))*($C$2-1%))-('Modelo Soja'!AW3/60*1000)-$C$6 -> #REF! | K3: =+(('Modelo Farelo'!AF3*(1+$C$8))*($C$3+1.5%)+('Modelo Oleo'!AE3*(1))*($C$2-1.5%))-('Modelo Soja'!AX3/60*1000)-$C$6 -> #REF! | L3: =+(('Modelo Farelo'!AG3*(1+$C$8))*($C$3+1.5%)+('Modelo Oleo'!AF3*(1))*($C$2-1.5%))-('Modelo Soja'!AY3/60*1000)-$C$6 -> #REF! | M3: =+(('Modelo Farelo'!AH3*(1+$C$8))*$C$3+('Modelo Oleo'!AG3*(1))*$C$2)-('Modelo Soja'!BM3/60*1000)-$C$6 -> #REF! | Q3: =+F3 -> 44197 | R3: =+(('Modelo Farelo'!AB3*(1+$C$8))*$C$3+('Modelo Oleo'!AA3*(1))*$C$2)-('Modelo Soja'!AK3/60*1000)-$C$6 -> #REF! | S3: =+(('Modelo Farelo'!AC3*(1+$C$8))*$C$3+('Modelo Oleo'!AB3*(1))*$C$2)-('Modelo Soja'!AA3/60*1000)-$C$6 -> #REF! | X3: =+(('Modelo Farelo'!AH3*(1+$C$8))*$C$3+('Modelo Oleo'!AG3*(1))*$C$2)-('Modelo Soja'!AL3/60*1000)-$C$6 -> #REF! | AK3: 2021 | AL3: =AVERAGEIF(E:E,AK3,M:M) -> #REF!
B4: Casca | C4: 0 | E4: =YEAR(F4) -> 2021 | F4: =+'Modelo Soja'!BA4 -> 44228 | G4: =+(('Modelo Farelo'!AB4*(1+$C$8))*$C$3+('Modelo Oleo'!AA4*(1))*$C$2)-('Modelo Soja'!AT4/60*1000)-$C$6 -> #REF! | H4: =+(('Modelo Farelo'!AC4*(1+$C$8))*$C$3+('Modelo Oleo'!AB4*(1))*$C$2)-('Modelo Soja'!AU4/60*1000)-$C$6 -> #REF! | I4: =+(('Modelo Farelo'!AD4*(1+$C$8))*$C$3+('Modelo Oleo'!AC4*(1))*$C$2)-('Modelo Soja'!AV4/60*1000)-$C$6 -> #REF! | J4: =+(('Modelo Farelo'!AE4*(1+$C$8))*($C$3+1%)+('Modelo Oleo'!AD4*(1))*($C$2-1%))-('Modelo Soja'!AW4/60*1000)-$C$6 -> #REF! | K4: =+(('Modelo Farelo'!AF4*(1+$C$8))*($C$3+1.5%)+('Modelo Oleo'!AE4*(1))*($C$2-1.5%))-('Modelo Soja'!AX4/60*1000)-$C$6 -> #REF! | L4: =+(('Modelo Farelo'!AG4*(1+$C$8))*($C$3+1.5%)+('Modelo Oleo'!AF4*(1))*($C$2-1.5%))-('Modelo Soja'!AY4/60*1000)-$C$6 -> #REF! | M4: =+(('Modelo Farelo'!AH4*(1+$C$8))*$C$3+('Modelo Oleo'!AG4*(1))*$C$2)-('Modelo Soja'!BM4/60*1000)-$C$6 -> #REF! | Q4: =+F4 -> 44228 | R4: =+(('Modelo Farelo'!AB4*(1+$C$8))*$C$3+('Modelo Oleo'!AA4*(1))*$C$2)-('Modelo Soja'!AK4/60*1000)-$C$6 -> #REF! | S4: =+(('Modelo Farelo'!AC4*(1+$C$8))*$C$3+('Modelo Oleo'!AB4*(1))*$C$2)-('Modelo Soja'!AA4/60*1000)-$C$6 -> #REF! | X4: =+(('Modelo Farelo'!AH4*(1+$C$8))*$C$3+('Modelo Oleo'!AG4*(1))*$C$2)-('Modelo Soja'!AL4/60*1000)-$C$6 -> #REF! | AK4: =+AK3+1 -> 2022 | AL4: =AVERAGEIF(E:E,AK4,M:M) -> #REF!
E5: =YEAR(F5) -> 2021 | F5: =+'Modelo Soja'!BA5 -> 44256 | G5: =+(('Modelo Farelo'!AB5*(1+$C$8))*$C$3+('Modelo Oleo'!AA5*(1))*$C$2)-('Modelo Soja'!AT5/60*1000)-$C$6 -> #REF! | H5: =+(('Modelo Farelo'!AC5*(1+$C$8))*$C$3+('Modelo Oleo'!AB5*(1))*$C$2)-('Modelo Soja'!AU5/60*1000)-$C$6 -> #REF! | I5: =+(('Modelo Farelo'!AD5*(1+$C$8))*$C$3+('Modelo Oleo'!AC5*(1))*$C$2)-('Modelo Soja'!AV5/60*1000)-$C$6 -> #REF! | J5: =+(('Modelo Farelo'!AE5*(1+$C$8))*($C$3+1%)+('Modelo Oleo'!AD5*(1))*($C$2-1%))-('Modelo Soja'!AW5/60*1000)-$C$6 -> #REF! | K5: =+(('Modelo Farelo'!AF5*(1+$C$8))*($C$3+1.5%)+('Modelo Oleo'!AE5*(1))*($C$2-1.5%))-('Modelo Soja'!AX5/60*1000)-$C$6 -> #REF! | L5: =+(('Modelo Farelo'!AG5*(1+$C$8))*($C$3+1.5%)+('Modelo Oleo'!AF5*(1))*($C$2-1.5%))-('Modelo Soja'!AY5/60*1000)-$C$6 -> #REF! | M5: =+(('Modelo Farelo'!AH5*(1+$C$8))*$C$3+('Modelo Oleo'!AG5*(1))*$C$2)-('Modelo Soja'!BM5/60*1000)-$C$6 -> #REF! | Q5: =+F5 -> 44256 | R5: =+(('Modelo Farelo'!AB5*(1+$C$8))*$C$3+('Modelo Oleo'!AA5*(1))*$C$2)-('Modelo Soja'!AK5/60*1000)-$C$6 -> #REF! | S5: =+(('Modelo Farelo'!AC5*(1+$C$8))*$C$3+('Modelo Oleo'!AB5*(1))*$C$2)-('Modelo Soja'!AA5/60*1000)-$C$6 -> #REF! | X5: =+(('Modelo Farelo'!AH5*(1+$C$8))*$C$3+('Modelo Oleo'!AG5*(1))*$C$2)-('Modelo Soja'!AL5/60*1000)-$C$6 -> #REF! | AK5: =+AK4+1 -> 2023 | AL5: =AVERAGEIF(E:E,AK5,M:M) -> #REF!
B6: Custo Industrial | C6: 160 | E6: =YEAR(F6) -> 2021 | F6: =+'Modelo Soja'!BA6 -> 44287 | G6: =+(('Modelo Farelo'!AB6*(1+$C$8))*$C$3+('Modelo Oleo'!AA6*(1))*$C$2)-('Modelo Soja'!AT6/60*1000)-$C$6 -> #REF! | H6: =+(('Modelo Farelo'!AC6*(1+$C$8))*$C$3+('Modelo Oleo'!AB6*(1))*$C$2)-('Modelo Soja'!AU6/60*1000)-$C$6 -> #REF! | I6: =+(('Modelo Farelo'!AD6*(1+$C$8))*$C$3+('Modelo Oleo'!AC6*(1))*$C$2)-('Modelo Soja'!AV6/60*1000)-$C$6 -> #REF! | J6: =+(('Modelo Farelo'!AE6*(1+$C$8))*($C$3+1%)+('Modelo Oleo'!AD6*(1))*($C$2-1%))-('Modelo Soja'!AW6/60*1000)-$C$6 -> #REF! | K6: =+(('Modelo Farelo'!AF6*(1+$C$8))*($C$3+1.5%)+('Modelo Oleo'!AE6*(1))*($C$2-1.5%))-('Modelo Soja'!AX6/60*1000)-$C$6 -> #REF! | L6: =+(('Modelo Farelo'!AG6*(1+$C$8))*($C$3+1.5%)+('Modelo Oleo'!AF6*(1))*($C$2-1.5%))-('Modelo Soja'!AY6/60*1000)-$C$6 -> #REF! | M6: =+(('Modelo Farelo'!AH6*(1+$C$8))*$C$3+('Modelo Oleo'!AG6*(1))*$C$2)-('Modelo Soja'!BM6/60*1000)-$C$6 -> #REF! | Q6: =+F6 -> 44287 | R6: =+(('Modelo Farelo'!AB6*(1+$C$8))*$C$3+('Modelo Oleo'!AA6*(1))*$C$2)-('Modelo Soja'!AK6/60*1000)-$C$6 -> #REF! | S6: =+(('Modelo Farelo'!AC6*(1+$C$8))*$C$3+('Modelo Oleo'!AB6*(1))*$C$2)-('Modelo Soja'!AA6/60*1000)-$C$6 -> #REF! | X6: =+(('Modelo Farelo'!AH6*(1+$C$8))*$C$3+('Modelo Oleo'!AG6*(1))*$C$2)-('Modelo Soja'!AL6/60*1000)-$C$6 -> #REF! | AK6: =+AK5+1 -> 2024 | AL6: =AVERAGEIF(E:E,AK6,M:M) -> #REF!
E7: =YEAR(F7) -> 2021 | F7: =+'Modelo Soja'!BA7 -> 44317 | G7: =+(('Modelo Farelo'!AB7*(1+$C$8))*$C$3+('Modelo Oleo'!AA7*(1))*$C$2)-('Modelo Soja'!AT7/60*1000)-$C$6 -> #REF! | H7: =+(('Modelo Farelo'!AC7*(1+$C$8))*$C$3+('Modelo Oleo'!AB7*(1))*$C$2)-('Modelo Soja'!AU7/60*1000)-$C$6 -> #REF! | I7: =+(('Modelo Farelo'!AD7*(1+$C$8))*$C$3+('Modelo Oleo'!AC7*(1))*$C$2)-('Modelo Soja'!AV7/60*1000)-$C$6 -> #REF! | J7: =+(('Modelo Farelo'!AE7*(1+$C$8))*($C$3+1%)+('Modelo Oleo'!AD7*(1))*($C$2-1%))-('Modelo Soja'!AW7/60*1000)-$C$6 -> #REF! | K7: =+(('Modelo Farelo'!AF7*(1+$C$8))*($C$3+1.5%)+('Modelo Oleo'!AE7*(1))*($C$2-1.5%))-('Modelo Soja'!AX7/60*1000)-$C$6 -> #REF! | L7: =+(('Modelo Farelo'!AG7*(1+$C$8))*($C$3+1.5%)+('Modelo Oleo'!AF7*(1))*($C$2-1.5%))-('Modelo Soja'!AY7/60*1000)-$C$6 -> #REF! | M7: =+(('Modelo Farelo'!AH7*(1+$C$8))*$C$3+('Modelo Oleo'!AG7*(1))*$C$2)-('Modelo Soja'!BM7/60*1000)-$C$6 -> #REF! | Q7: =+F7 -> 44317 | R7: =+(('Modelo Farelo'!AB7*(1+$C$8))*$C$3+('Modelo Oleo'!AA7*(1))*$C$2)-('Modelo Soja'!AK7/60*1000)-$C$6 -> #REF! | S7: =+(('Modelo Farelo'!AC7*(1+$C$8))*$C$3+('Modelo Oleo'!AB7*(1))*$C$2)-('Modelo Soja'!AA7/60*1000)-$C$6 -> #REF! | X7: =+(('Modelo Farelo'!AH7*(1+$C$8))*$C$3+('Modelo Oleo'!AG7*(1))*$C$2)-('Modelo Soja'!AL7/60*1000)-$C$6 -> #REF! | AK7: =+AK6+1 -> 2025 | AL7: =AVERAGEIF(E:E,AK7,M:M) -> #REF!
B8: Pis/Cofins | C8: 0.0225 | E8: =YEAR(F8) -> 2021 | F8: =+'Modelo Soja'!BA8 -> 44348 | G8: =+(('Modelo Farelo'!AB8*(1+$C$8))*$C$3+('Modelo Oleo'!AA8*(1))*$C$2)-('Modelo Soja'!AT8/60*1000)-$C$6 -> #REF! | H8: =+(('Modelo Farelo'!AC8*(1+$C$8))*$C$3+('Modelo Oleo'!AB8*(1))*$C$2)-('Modelo Soja'!AU8/60*1000)-$C$6 -> #REF! | I8: =+(('Modelo Farelo'!AD8*(1+$C$8))*$C$3+('Modelo Oleo'!AC8*(1))*$C$2)-('Modelo Soja'!AV8/60*1000)-$C$6 -> #REF! | J8: =+(('Modelo Farelo'!AE8*(1+$C$8))*($C$3+1%)+('Modelo Oleo'!AD8*(1))*($C$2-1%))-('Modelo Soja'!AW8/60*1000)-$C$6 -> #REF! | K8: =+(('Modelo Farelo'!AF8*(1+$C$8))*($C$3+1.5%)+('Modelo Oleo'!AE8*(1))*($C$2-1.5%))-('Modelo Soja'!AX8/60*1000)-$C$6 -> #REF! | L8: =+(('Modelo Farelo'!AG8*(1+$C$8))*($C$3+1.5%)+('Modelo Oleo'!AF8*(1))*($C$2-1.5%))-('Modelo Soja'!AY8/60*1000)-$C$6 -> #REF! | M8: =+(('Modelo Farelo'!AH8*(1+$C$8))*$C$3+('Modelo Oleo'!AG8*(1))*$C$2)-('Modelo Soja'!BM8/60*1000)-$C$6 -> #REF! | Q8: =+F8 -> 44348 | R8: =+(('Modelo Farelo'!AB8*(1+$C$8))*$C$3+('Modelo Oleo'!AA8*(1))*$C$2)-('Modelo Soja'!AK8/60*1000)-$C$6 -> #REF! | S8: =+(('Modelo Farelo'!AC8*(1+$C$8))*$C$3+('Modelo Oleo'!AB8*(1))*$C$2)-('Modelo Soja'!AA8/60*1000)-$C$6 -> #REF! | X8: =+(('Modelo Farelo'!AH8*(1+$C$8))*$C$3+('Modelo Oleo'!AG8*(1))*$C$2)-('Modelo Soja'!AL8/60*1000)-$C$6 -> #REF! | AK8: =+AK7+1 -> 2026 | AL8: =AVERAGEIF(E:E,AK8,M:M) -> #REF!
E9: =YEAR(F9) -> 2021 | F9: =+'Modelo Soja'!BA9 -> 44378 | G9: =+(('Modelo Farelo'!AB9*(1+$C$8))*$C$3+('Modelo Oleo'!AA9*(1))*$C$2)-('Modelo Soja'!AT9/60*1000)-$C$6 -> #REF! | H9: =+(('Modelo Farelo'!AC9*(1+$C$8))*$C$3+('Modelo Oleo'!AB9*(1))*$C$2)-('Modelo Soja'!AU9/60*1000)-$C$6 -> #REF! | I9: =+(('Modelo Farelo'!AD9*(1+$C$8))*$C$3+('Modelo Oleo'!AC9*(1))*$C$2)-('Modelo Soja'!AV9/60*1000)-$C$6 -> #REF! | J9: =+(('Modelo Farelo'!AE9*(1+$C$8))*($C$3+1%)+('Modelo Oleo'!AD9*(1))*($C$2-1%))-('Modelo Soja'!AW9/60*1000)-$C$6 -> #REF! | K9: =+(('Modelo Farelo'!AF9*(1+$C$8))*($C$3+1.5%)+('Modelo Oleo'!AE9*(1))*($C$2-1.5%))-('Modelo Soja'!AX9/60*1000)-$C$6 -> #REF! | L9: =+(('Modelo Farelo'!AG9*(1+$C$8))*($C$3+1.5%)+('Modelo Oleo'!AF9*(1))*($C$2-1.5%))-('Modelo Soja'!AY9/60*1000)-$C$6 -> #REF! | M9: =+(('Modelo Farelo'!AH9*(1+$C$8))*$C$3+('Modelo Oleo'!AG9*(1))*$C$2)-('Modelo Soja'!BM9/60*1000)-$C$6 -> #REF! | Q9: =+F9 -> 44378 | R9: =+(('Modelo Farelo'!AB9*(1+$C$8))*$C$3+('Modelo Oleo'!AA9*(1))*$C$2)-('Modelo Soja'!AK9/60*1000)-$C$6 -> #REF! | S9: =+(('Modelo Farelo'!AC9*(1+$C$8))*$C$3+('Modelo Oleo'!AB9*(1))*$C$2)-('Modelo Soja'!AA9/60*1000)-$C$6 -> #REF! | X9: =+(('Modelo Farelo'!AH9*(1+$C$8))*$C$3+('Modelo Oleo'!AG9*(1))*$C$2)-('Modelo Soja'!AL9/60*1000)-$C$6 -> #REF!
E10: =YEAR(F10) -> 2021 | F10: =+'Modelo Soja'!BA10 -> 44409 | G10: =+(('Modelo Farelo'!AB10*(1+$C$8))*$C$3+('Modelo Oleo'!AA10*(1))*$C$2)-('Modelo Soja'!AT10/60*1000)-$C$6 -> #REF! | H10: =+(('Modelo Farelo'!AC10*(1+$C$8))*$C$3+('Modelo Oleo'!AB10*(1))*$C$2)-('Modelo Soja'!AU10/60*1000)-$C$6 -> #REF! | I10: =+(('Modelo Farelo'!AD10*(1+$C$8))*$C$3+('Modelo Oleo'!AC10*(1))*$C$2)-('Modelo Soja'!AV10/60*1000)-$C$6 -> #REF! | J10: =+(('Modelo Farelo'!AE10*(1+$C$8))*($C$3+1%)+('Modelo Oleo'!AD10*(1))*($C$2-1%))-('Modelo Soja'!AW10/60*1000)-$C$6 -> #REF! | K10: =+(('Modelo Farelo'!AF10*(1+$C$8))*($C$3+1.5%)+('Modelo Oleo'!AE10*(1))*($C$2-1.5%))-('Modelo Soja'!AX10/60*1000)-$C$6 -> #REF! | L10: =+(('Modelo Farelo'!AG10*(1+$C$8))*($C$3+1.5%)+('Modelo Oleo'!AF10*(1))*($C$2-1.5%))-('Modelo Soja'!AY10/60*1000)-$C$6 -> #REF! | M10: =+(('Modelo Farelo'!AH10*(1+$C$8))*$C$3+('Modelo Oleo'!AG10*(1))*$C$2)-('Modelo Soja'!BM10/60*1000)-$C$6 -> #REF! | Q10: =+F10 -> 44409 | R10: =+(('Modelo Farelo'!AB10*(1+$C$8))*$C$3+('Modelo Oleo'!AA10*(1))*$C$2)-('Modelo Soja'!AK10/60*1000)-$C$6 -> #REF! | S10: =+(('Modelo Farelo'!AC10*(1+$C$8))*$C$3+('Modelo Oleo'!AB10*(1))*$C$2)-('Modelo Soja'!AA10/60*1000)-$C$6 -> #REF! | X10: =+(('Modelo Farelo'!AH10*(1+$C$8))*$C$3+('Modelo Oleo'!AG10*(1))*$C$2)-('Modelo Soja'!AL10/60*1000)-$C$6 -> #REF! | AK10: 2021 | AL10: =AVERAGEIF(E:E,AK3,X:X) -> #REF!
E11: =YEAR(F11) -> 2021 | F11: =+'Modelo Soja'!BA11 -> 44440 | G11: =+(('Modelo Farelo'!AB11*(1+$C$8))*$C$3+('Modelo Oleo'!AA11*(1))*$C$2)-('Modelo Soja'!AT11/60*1000)-$C$6 -> #REF! | H11: =+(('Modelo Farelo'!AC11*(1+$C$8))*$C$3+('Modelo Oleo'!AB11*(1))*$C$2)-('Modelo Soja'!AU11/60*1000)-$C$6 -> #REF! | I11: =+(('Modelo Farelo'!AD11*(1+$C$8))*$C$3+('Modelo Oleo'!AC11*(1))*$C$2)-('Modelo Soja'!AV11/60*1000)-$C$6 -> #REF! | J11: =+(('Modelo Farelo'!AE11*(1+$C$8))*($C$3+1%)+('Modelo Oleo'!AD11*(1))*($C$2-1%))-('Modelo Soja'!AW11/60*1000)-$C$6 -> #REF! | K11: =+(('Modelo Farelo'!AF11*(1+$C$8))*($C$3+1.5%)+('Modelo Oleo'!AE11*(1))*($C$2-1.5%))-('Modelo Soja'!AX11/60*1000)-$C$6 -> #REF! | L11: =+(('Modelo Farelo'!AG11*(1+$C$8))*($C$3+1.5%)+('Modelo Oleo'!AF11*(1))*($C$2-1.5%))-('Modelo Soja'!AY11/60*1000)-$C$6 -> #REF! | M11: =+(('Modelo Farelo'!AH11*(1+$C$8))*$C$3+('Modelo Oleo'!AG11*(1))*$C$2)-('Modelo Soja'!BM11/60*1000)-$C$6 -> #REF! | Q11: =+F11 -> 44440 | R11: =+(('Modelo Farelo'!AB11*(1+$C$8))*$C$3+('Modelo Oleo'!AA11*(1))*$C$2)-('Modelo Soja'!AK11/60*1000)-$C$6 -> #REF! | S11: =+(('Modelo Farelo'!AC11*(1+$C$8))*$C$3+('Modelo Oleo'!AB11*(1))*$C$2)-('Modelo Soja'!AA11/60*1000)-$C$6 -> #REF! | X11: =+(('Modelo Farelo'!AH11*(1+$C$8))*$C$3+('Modelo Oleo'!AG11*(1))*$C$2)-('Modelo Soja'!AL11/60*1000)-$C$6 -> #REF! | AK11: =+AK10+1 -> 2022 | AL11: =AVERAGEIF(E:E,AK4,X:X) -> #REF!
E12: =YEAR(F12) -> 2021 | F12: =+'Modelo Soja'!BA12 -> 44470 | G12: =+(('Modelo Farelo'!AB12*(1+$C$8))*$C$3+('Modelo Oleo'!AA12*(1))*$C$2)-('Modelo Soja'!AT12/60*1000)-$C$6 -> #REF! | H12: =+(('Modelo Farelo'!AC12*(1+$C$8))*$C$3+('Modelo Oleo'!AB12*(1))*$C$2)-('Modelo Soja'!AU12/60*1000)-$C$6 -> #REF! | I12: =+(('Modelo Farelo'!AD12*(1+$C$8))*$C$3+('Modelo Oleo'!AC12*(1))*$C$2)-('Modelo Soja'!AV12/60*1000)-$C$6 -> #REF! | J12: =+(('Modelo Farelo'!AE12*(1+$C$8))*($C$3+1%)+('Modelo Oleo'!AD12*(1))*($C$2-1%))-('Modelo Soja'!AW12/60*1000)-$C$6 -> #REF! | K12: =+(('Modelo Farelo'!AF12*(1+$C$8))*($C$3+1.5%)+('Modelo Oleo'!AE12*(1))*($C$2-1.5%))-('Modelo Soja'!AX12/60*1000)-$C$6 -> #REF! | L12: =+(('Modelo Farelo'!AG12*(1+$C$8))*($C$3+1.5%)+('Modelo Oleo'!AF12*(1))*($C$2-1.5%))-('Modelo Soja'!AY12/60*1000)-$C$6 -> #REF! | M12: =+(('Modelo Farelo'!AH12*(1+$C$8))*$C$3+('Modelo Oleo'!AG12*(1))*$C$2)-('Modelo Soja'!BM12/60*1000)-$C$6 -> #REF! | Q12: =+F12 -> 44470 | R12: =+(('Modelo Farelo'!AB12*(1+$C$8))*$C$3+('Modelo Oleo'!AA12*(1))*$C$2)-('Modelo Soja'!AK12/60*1000)-$C$6 -> #REF! | S12: =+(('Modelo Farelo'!AC12*(1+$C$8))*$C$3+('Modelo Oleo'!AB12*(1))*$C$2)-('Modelo Soja'!AA12/60*1000)-$C$6 -> #REF! | X12: =+(('Modelo Farelo'!AH12*(1+$C$8))*$C$3+('Modelo Oleo'!AG12*(1))*$C$2)-('Modelo Soja'!AL12/60*1000)-$C$6 -> #REF! | AK12: =+AK11+1 -> 2023 | AL12: =AVERAGEIF(E:E,AK5,X:X) -> #REF!
E13: =YEAR(F13) -> 2021 | F13: =+'Modelo Soja'!BA13 -> 44501 | G13: =+(('Modelo Farelo'!AB13*(1+$C$8))*$C$3+('Modelo Oleo'!AA13*(1))*$C$2)-('Modelo Soja'!AT13/60*1000)-$C$6 -> #REF! | H13: =+(('Modelo Farelo'!AC13*(1+$C$8))*$C$3+('Modelo Oleo'!AB13*(1))*$C$2)-('Modelo Soja'!AU13/60*1000)-$C$6 -> #REF! | I13: =+(('Modelo Farelo'!AD13*(1+$C$8))*$C$3+('Modelo Oleo'!AC13*(1))*$C$2)-('Modelo Soja'!AV13/60*1000)-$C$6 -> #REF! | J13: =+(('Modelo Farelo'!AE13*(1+$C$8))*($C$3+1%)+('Modelo Oleo'!AD13*(1))*($C$2-1%))-('Modelo Soja'!AW13/60*1000)-$C$6 -> #REF! | K13: =+(('Modelo Farelo'!AF13*(1+$C$8))*($C$3+1.5%)+('Modelo Oleo'!AE13*(1))*($C$2-1.5%))-('Modelo Soja'!AX13/60*1000)-$C$6 -> #REF! | L13: =+(('Modelo Farelo'!AG13*(1+$C$8))*($C$3+1.5%)+('Modelo Oleo'!AF13*(1))*($C$2-1.5%))-('Modelo Soja'!AY13/60*1000)-$C$6 -> #REF! | M13: =+(('Modelo Farelo'!AH13*(1+$C$8))*$C$3+('Modelo Oleo'!AG13*(1))*$C$2)-('Modelo Soja'!BM13/60*1000)-$C$6 -> #REF! | Q13: =+F13 -> 44501 | R13: =+(('Modelo Farelo'!AB13*(1+$C$8))*$C$3+('Modelo Oleo'!AA13*(1))*$C$2)-('Modelo Soja'!AK13/60*1000)-$C$6 -> #REF! | S13: =+(('Modelo Farelo'!AC13*(1+$C$8))*$C$3+('Modelo Oleo'!AB13*(1))*$C$2)-('Modelo Soja'!AA13/60*1000)-$C$6 -> #REF! | X13: =+(('Modelo Farelo'!AH13*(1+$C$8))*$C$3+('Modelo Oleo'!AG13*(1))*$C$2)-('Modelo Soja'!AL13/60*1000)-$C$6 -> #REF! | AK13: =+AK12+1 -> 2024 | AL13: =AVERAGEIF(E:E,AK6,X:X) -> #REF!
E14: =YEAR(F14) -> 2021 | F14: =+'Modelo Soja'!BA14 -> 44531 | G14: =+(('Modelo Farelo'!AB14*(1+$C$8))*$C$3+('Modelo Oleo'!AA14*(1))*$C$2)-('Modelo Soja'!AT14/60*1000)-$C$6 -> #REF! | H14: =+(('Modelo Farelo'!AC14*(1+$C$8))*$C$3+('Modelo Oleo'!AB14*(1))*$C$2)-('Modelo Soja'!AU14/60*1000)-$C$6 -> #REF! | I14: =+(('Modelo Farelo'!AD14*(1+$C$8))*$C$3+('Modelo Oleo'!AC14*(1))*$C$2)-('Modelo Soja'!AV14/60*1000)-$C$6 -> #REF! | J14: =+(('Modelo Farelo'!AE14*(1+$C$8))*($C$3+1%)+('Modelo Oleo'!AD14*(1))*($C$2-1%))-('Modelo Soja'!AW14/60*1000)-$C$6 -> #REF! | K14: =+(('Modelo Farelo'!AF14*(1+$C$8))*($C$3+1.5%)+('Modelo Oleo'!AE14*(1))*($C$2-1.5%))-('Modelo Soja'!AX14/60*1000)-$C$6 -> #REF! | L14: =+(('Modelo Farelo'!AG14*(1+$C$8))*($C$3+1.5%)+('Modelo Oleo'!AF14*(1))*($C$2-1.5%))-('Modelo Soja'!AY14/60*1000)-$C$6 -> #REF! | M14: =+(('Modelo Farelo'!AH14*(1+$C$8))*$C$3+('Modelo Oleo'!AG14*(1))*$C$2)-('Modelo Soja'!BM14/60*1000)-$C$6 -> #REF! | Q14: =+F14 -> 44531 | R14: =+(('Modelo Farelo'!AB14*(1+$C$8))*$C$3+('Modelo Oleo'!AA14*(1))*$C$2)-('Modelo Soja'!AK14/60*1000)-$C$6 -> #REF! | S14: =+(('Modelo Farelo'!AC14*(1+$C$8))*$C$3+('Modelo Oleo'!AB14*(1))*$C$2)-('Modelo Soja'!AA14/60*1000)-$C$6 -> #REF! | X14: =+(('Modelo Farelo'!AH14*(1+$C$8))*$C$3+('Modelo Oleo'!AG14*(1))*$C$2)-('Modelo Soja'!AL14/60*1000)-$C$6 -> #REF! | AK14: =+AK13+1 -> 2025 | AL14: =AVERAGEIF(E:E,AK7,X:X) -> #REF!
E15: =YEAR(F15) -> 2022 | F15: =+'Modelo Soja'!BA15 -> 44562 | G15: =+(('Modelo Farelo'!AB15*(1+$C$8))*$C$3+('Modelo Oleo'!AA15*(1))*$C$2)-('Modelo Soja'!AT15/60*1000)-$C$6 -> #REF! | H15: =+(('Modelo Farelo'!AC15*(1+$C$8))*$C$3+('Modelo Oleo'!AB15*(1))*$C$2)-('Modelo Soja'!AU15/60*1000)-$C$6 -> #REF! | I15: =+(('Modelo Farelo'!AD15*(1+$C$8))*$C$3+('Modelo Oleo'!AC15*(1))*$C$2)-('Modelo Soja'!AV15/60*1000)-$C$6 -> #REF! | J15: =+(('Modelo Farelo'!AE15*(1+$C$8))*($C$3+1%)+('Modelo Oleo'!AD15*(1))*($C$2-1%))-('Modelo Soja'!AW15/60*1000)-$C$6 -> #REF! | K15: =+(('Modelo Farelo'!AF15*(1+$C$8))*($C$3+1.5%)+('Modelo Oleo'!AE15*(1))*($C$2-1.5%))-('Modelo Soja'!AX15/60*1000)-$C$6 -> #REF! | L15: =+(('Modelo Farelo'!AG15*(1+$C$8))*($C$3+1.5%)+('Modelo Oleo'!AF15*(1))*($C$2-1.5%))-('Modelo Soja'!AY15/60*1000)-$C$6 -> #REF! | M15: =+(('Modelo Farelo'!AH15*(1+$C$8))*$C$3+('Modelo Oleo'!AG15*(1))*$C$2)-('Modelo Soja'!BM15/60*1000)-$C$6 -> #REF! | Q15: =+F15 -> 44562 | R15: =+(('Modelo Farelo'!AB15*(1+$C$8))*$C$3+('Modelo Oleo'!AA15*(1))*$C$2)-('Modelo Soja'!AK15/60*1000)-$C$6 -> #REF! | S15: =+(('Modelo Farelo'!AC15*(1+$C$8))*$C$3+('Modelo Oleo'!AB15*(1))*$C$2)-('Modelo Soja'!AA15/60*1000)-$C$6 -> #REF! | X15: =+(('Modelo Farelo'!AH15*(1+$C$8))*$C$3+('Modelo Oleo'!AG15*(1))*$C$2)-('Modelo Soja'!AL15/60*1000)-$C$6 -> #REF! | AK15: =+AK14+1 -> 2026 | AL15: =AVERAGEIF(E:E,AK8,X:X) -> #REF!
E16: =YEAR(F16) -> 2022 | F16: =+'Modelo Soja'!BA16 -> 44593 | G16: =+(('Modelo Farelo'!AB16*(1+$C$8))*$C$3+('Modelo Oleo'!AA16*(1))*$C$2)-('Modelo Soja'!AT16/60*1000)-$C$6 -> #REF! | H16: =+(('Modelo Farelo'!AC16*(1+$C$8))*$C$3+('Modelo Oleo'!AB16*(1))*$C$2)-('Modelo Soja'!AU16/60*1000)-$C$6 -> #REF! | I16: =+(('Modelo Farelo'!AD16*(1+$C$8))*$C$3+('Modelo Oleo'!AC16*(1))*$C$2)-('Modelo Soja'!AV16/60*1000)-$C$6 -> #REF! | J16: =+(('Modelo Farelo'!AE16*(1+$C$8))*($C$3+1%)+('Modelo Oleo'!AD16*(1))*($C$2-1%))-('Modelo Soja'!AW16/60*1000)-$C$6 -> #REF! | K16: =+(('Modelo Farelo'!AF16*(1+$C$8))*($C$3+1.5%)+('Modelo Oleo'!AE16*(1))*($C$2-1.5%))-('Modelo Soja'!AX16/60*1000)-$C$6 -> #REF! | L16: =+(('Modelo Farelo'!AG16*(1+$C$8))*($C$3+1.5%)+('Modelo Oleo'!AF16*(1))*($C$2-1.5%))-('Modelo Soja'!AY16/60*1000)-$C$6 -> #REF! | M16: =+(('Modelo Farelo'!AH16*(1+$C$8))*$C$3+('Modelo Oleo'!AG16*(1))*$C$2)-('Modelo Soja'!BM16/60*1000)-$C$6 -> #REF! | Q16: =+F16 -> 44593 | R16: =+(('Modelo Farelo'!AB16*(1+$C$8))*$C$3+('Modelo Oleo'!AA16*(1))*$C$2)-('Modelo Soja'!AK16/60*1000)-$C$6 -> #REF! | S16: =+(('Modelo Farelo'!AC16*(1+$C$8))*$C$3+('Modelo Oleo'!AB16*(1))*$C$2)-('Modelo Soja'!AA16/60*1000)-$C$6 -> #REF! | X16: =+(('Modelo Farelo'!AH16*(1+$C$8))*$C$3+('Modelo Oleo'!AG16*(1))*$C$2)-('Modelo Soja'!AL16/60*1000)-$C$6 -> #REF!
E17: =YEAR(F17) -> 2022 | F17: =+'Modelo Soja'!BA17 -> 44621 | G17: =+(('Modelo Farelo'!AB17*(1+$C$8))*$C$3+('Modelo Oleo'!AA17*(1))*$C$2)-('Modelo Soja'!AT17/60*1000)-$C$6 -> #REF! | H17: =+(('Modelo Farelo'!AC17*(1+$C$8))*$C$3+('Modelo Oleo'!AB17*(1))*$C$2)-('Modelo Soja'!AU17/60*1000)-$C$6 -> #REF! | I17: =+(('Modelo Farelo'!AD17*(1+$C$8))*$C$3+('Modelo Oleo'!AC17*(1))*$C$2)-('Modelo Soja'!AV17/60*1000)-$C$6 -> #REF! | J17: =+(('Modelo Farelo'!AE17*(1+$C$8))*($C$3+1%)+('Modelo Oleo'!AD17*(1))*($C$2-1%))-('Modelo Soja'!AW17/60*1000)-$C$6 -> #REF! | K17: =+(('Modelo Farelo'!AF17*(1+$C$8))*($C$3+1.5%)+('Modelo Oleo'!AE17*(1))*($C$2-1.5%))-('Modelo Soja'!AX17/60*1000)-$C$6 -> #REF! | L17: =+(('Modelo Farelo'!AG17*(1+$C$8))*($C$3+1.5%)+('Modelo Oleo'!AF17*(1))*($C$2-1.5%))-('Modelo Soja'!AY17/60*1000)-$C$6 -> #REF! | M17: =+(('Modelo Farelo'!AH17*(1+$C$8))*$C$3+('Modelo Oleo'!AG17*(1))*$C$2)-('Modelo Soja'!BM17/60*1000)-$C$6 -> #REF! | Q17: =+F17 -> 44621 | R17: =+(('Modelo Farelo'!AB17*(1+$C$8))*$C$3+('Modelo Oleo'!AA17*(1))*$C$2)-('Modelo Soja'!AK17/60*1000)-$C$6 -> #REF! | S17: =+(('Modelo Farelo'!AC17*(1+$C$8))*$C$3+('Modelo Oleo'!AB17*(1))*$C$2)-('Modelo Soja'!AA17/60*1000)-$C$6 -> #REF! | X17: =+(('Modelo Farelo'!AH17*(1+$C$8))*$C$3+('Modelo Oleo'!AG17*(1))*$C$2)-('Modelo Soja'!AL17/60*1000)-$C$6 -> #REF!
E18: =YEAR(F18) -> 2022 | F18: =+'Modelo Soja'!BA18 -> 44652 | G18: =+(('Modelo Farelo'!AB18*(1+$C$8))*$C$3+('Modelo Oleo'!AA18*(1))*$C$2)-('Modelo Soja'!AT18/60*1000)-$C$6 -> #REF! | H18: =+(('Modelo Farelo'!AC18*(1+$C$8))*$C$3+('Modelo Oleo'!AB18*(1))*$C$2)-('Modelo Soja'!AU18/60*1000)-$C$6 -> #REF! | I18: =+(('Modelo Farelo'!AD18*(1+$C$8))*$C$3+('Modelo Oleo'!AC18*(1))*$C$2)-('Modelo Soja'!AV18/60*1000)-$C$6 -> #REF! | J18: =+(('Modelo Farelo'!AE18*(1+$C$8))*($C$3+1%)+('Modelo Oleo'!AD18*(1))*($C$2-1%))-('Modelo Soja'!AW18/60*1000)-$C$6 -> #REF! | K18: =+(('Modelo Farelo'!AF18*(1+$C$8))*($C$3+1.5%)+('Modelo Oleo'!AE18*(1))*($C$2-1.5%))-('Modelo Soja'!AX18/60*1000)-$C$6 -> #REF! | L18: =+(('Modelo Farelo'!AG18*(1+$C$8))*($C$3+1.5%)+('Modelo Oleo'!AF18*(1))*($C$2-1.5%))-('Modelo Soja'!AY18/60*1000)-$C$6 -> #REF! | M18: =+(('Modelo Farelo'!AH18*(1+$C$8))*$C$3+('Modelo Oleo'!AG18*(1))*$C$2)-('Modelo Soja'!BM18/60*1000)-$C$6 -> #REF! | Q18: =+F18 -> 44652 | R18: =+(('Modelo Farelo'!AB18*(1+$C$8))*$C$3+('Modelo Oleo'!AA18*(1))*$C$2)-('Modelo Soja'!AK18/60*1000)-$C$6 -> #REF! | S18: =+(('Modelo Farelo'!AC18*(1+$C$8))*$C$3+('Modelo Oleo'!AB18*(1))*$C$2)-('Modelo Soja'!AA18/60*1000)-$C$6 -> #REF! | X18: =+(('Modelo Farelo'!AH18*(1+$C$8))*$C$3+('Modelo Oleo'!AG18*(1))*$C$2)-('Modelo Soja'!AL18/60*1000)-$C$6 -> #REF!
E19: =YEAR(F19) -> 2022 | F19: =+'Modelo Soja'!BA19 -> 44682 | G19: =+(('Modelo Farelo'!AB19*(1+$C$8))*$C$3+('Modelo Oleo'!AA19*(1))*$C$2)-('Modelo Soja'!AT19/60*1000)-$C$6 -> #REF! | H19: =+(('Modelo Farelo'!AC19*(1+$C$8))*$C$3+('Modelo Oleo'!AB19*(1))*$C$2)-('Modelo Soja'!AU19/60*1000)-$C$6 -> #REF! | I19: =+(('Modelo Farelo'!AD19*(1+$C$8))*$C$3+('Modelo Oleo'!AC19*(1))*$C$2)-('Modelo Soja'!AV19/60*1000)-$C$6 -> #REF! | J19: =+(('Modelo Farelo'!AE19*(1+$C$8))*($C$3+1%)+('Modelo Oleo'!AD19*(1))*($C$2-1%))-('Modelo Soja'!AW19/60*1000)-$C$6 -> #REF! | K19: =+(('Modelo Farelo'!AF19*(1+$C$8))*($C$3+1.5%)+('Modelo Oleo'!AE19*(1))*($C$2-1.5%))-('Modelo Soja'!AX19/60*1000)-$C$6 -> #REF! | L19: =+(('Modelo Farelo'!AG19*(1+$C$8))*($C$3+1.5%)+('Modelo Oleo'!AF19*(1))*($C$2-1.5%))-('Modelo Soja'!AY19/60*1000)-$C$6 -> #REF! | M19: =+(('Modelo Farelo'!AH19*(1+$C$8))*$C$3+('Modelo Oleo'!AG19*(1))*$C$2)-('Modelo Soja'!BM19/60*1000)-$C$6 -> #REF! | Q19: =+F19 -> 44682 | R19: =+(('Modelo Farelo'!AB19*(1+$C$8))*$C$3+('Modelo Oleo'!AA19*(1))*$C$2)-('Modelo Soja'!AK19/60*1000)-$C$6 -> #REF! | S19: =+(('Modelo Farelo'!AC19*(1+$C$8))*$C$3+('Modelo Oleo'!AB19*(1))*$C$2)-('Modelo Soja'!AA19/60*1000)-$C$6 -> #REF! | X19: =+(('Modelo Farelo'!AH19*(1+$C$8))*$C$3+('Modelo Oleo'!AG19*(1))*$C$2)-('Modelo Soja'!AL19/60*1000)-$C$6 -> #REF!
E20: =YEAR(F20) -> 2022 | F20: =+'Modelo Soja'!BA20 -> 44713 | G20: =+(('Modelo Farelo'!AB20*(1+$C$8))*$C$3+('Modelo Oleo'!AA20*(1))*$C$2)-('Modelo Soja'!AT20/60*1000)-$C$6 -> #REF! | H20: =+(('Modelo Farelo'!AC20*(1+$C$8))*$C$3+('Modelo Oleo'!AB20*(1))*$C$2)-('Modelo Soja'!AU20/60*1000)-$C$6 -> #REF! | I20: =+(('Modelo Farelo'!AD20*(1+$C$8))*$C$3+('Modelo Oleo'!AC20*(1))*$C$2)-('Modelo Soja'!AV20/60*1000)-$C$6 -> #REF! | J20: =+(('Modelo Farelo'!AE20*(1+$C$8))*($C$3+1%)+('Modelo Oleo'!AD20*(1))*($C$2-1%))-('Modelo Soja'!AW20/60*1000)-$C$6 -> #REF! | K20: =+(('Modelo Farelo'!AF20*(1+$C$8))*($C$3+1.5%)+('Modelo Oleo'!AE20*(1))*($C$2-1.5%))-('Modelo Soja'!AX20/60*1000)-$C$6 -> #REF! | L20: =+(('Modelo Farelo'!AG20*(1+$C$8))*($C$3+1.5%)+('Modelo Oleo'!AF20*(1))*($C$2-1.5%))-('Modelo Soja'!AY20/60*1000)-$C$6 -> #REF! | M20: =+(('Modelo Farelo'!AH20*(1+$C$8))*$C$3+('Modelo Oleo'!AG20*(1))*$C$2)-('Modelo Soja'!BM20/60*1000)-$C$6 -> #REF! | Q20: =+F20 -> 44713 | R20: =+(('Modelo Farelo'!AB20*(1+$C$8))*$C$3+('Modelo Oleo'!AA20*(1))*$C$2)-('Modelo Soja'!AK20/60*1000)-$C$6 -> #REF! | S20: =+(('Modelo Farelo'!AC20*(1+$C$8))*$C$3+('Modelo Oleo'!AB20*(1))*$C$2)-('Modelo Soja'!AA20/60*1000)-$C$6 -> #REF! | X20: =+(('Modelo Farelo'!AH20*(1+$C$8))*$C$3+('Modelo Oleo'!AG20*(1))*$C$2)-('Modelo Soja'!AL20/60*1000)-$C$6 -> #REF!
E21: =YEAR(F21) -> 2022 | F21: =+'Modelo Soja'!BA21 -> 44743 | G21: =+(('Modelo Farelo'!AB21*(1+$C$8))*$C$3+('Modelo Oleo'!AA21*(1))*$C$2)-('Modelo Soja'!AT21/60*1000)-$C$6 -> #REF! | H21: =+(('Modelo Farelo'!AC21*(1+$C$8))*$C$3+('Modelo Oleo'!AB21*(1))*$C$2)-('Modelo Soja'!AU21/60*1000)-$C$6 -> #REF! | I21: =+(('Modelo Farelo'!AD21*(1+$C$8))*$C$3+('Modelo Oleo'!AC21*(1))*$C$2)-('Modelo Soja'!AV21/60*1000)-$C$6 -> #REF! | J21: =+(('Modelo Farelo'!AE21*(1+$C$8))*($C$3+1%)+('Modelo Oleo'!AD21*(1))*($C$2-1%))-('Modelo Soja'!AW21/60*1000)-$C$6 -> #REF! | K21: =+(('Modelo Farelo'!AF21*(1+$C$8))*($C$3+1.5%)+('Modelo Oleo'!AE21*(1))*($C$2-1.5%))-('Modelo Soja'!AX21/60*1000)-$C$6 -> #REF! | L21: =+(('Modelo Farelo'!AG21*(1+$C$8))*($C$3+1.5%)+('Modelo Oleo'!AF21*(1))*($C$2-1.5%))-('Modelo Soja'!AY21/60*1000)-$C$6 -> #REF! | M21: =+(('Modelo Farelo'!AH21*(1+$C$8))*$C$3+('Modelo Oleo'!AG21*(1))*$C$2)-('Modelo Soja'!BM21/60*1000)-$C$6 -> #REF! | Q21: =+F21 -> 44743 | R21: =+(('Modelo Farelo'!AB21*(1+$C$8))*$C$3+('Modelo Oleo'!AA21*(1))*$C$2)-('Modelo Soja'!AK21/60*1000)-$C$6 -> #REF! | S21: =+(('Modelo Farelo'!AC21*(1+$C$8))*$C$3+('Modelo Oleo'!AB21*(1))*$C$2)-('Modelo Soja'!AA21/60*1000)-$C$6 -> #REF! | X21: =+(('Modelo Farelo'!AH21*(1+$C$8))*$C$3+('Modelo Oleo'!AG21*(1))*$C$2)-('Modelo Soja'!AL21/60*1000)-$C$6 -> #REF!
